[2023-12-28 18:10:58,156][django.request.log_response():222] [ERROR] Internal Server Error: /admin/upload
Traceback (most recent call last):
  File "/Users/mac/Desktop/work/game-server/venv/lib/python3.11/site-packages/django/core/handlers/exception.py", line 34, in inner
    response = get_response(request)
               ^^^^^^^^^^^^^^^^^^^^^
  File "/Users/mac/Desktop/work/game-server/venv/lib/python3.11/site-packages/django/utils/deprecation.py", line 93, in __call__
    response = self.process_request(request)
               ^^^^^^^^^^^^^^^^^^^^^^^^^^^^^
  File "/Users/mac/Desktop/work/game-server/venv/lib/python3.11/site-packages/django/middleware/common.py", line 53, in process_request
    path = self.get_full_path_with_slash(request)
           ^^^^^^^^^^^^^^^^^^^^^^^^^^^^^^^^^^^^^^
  File "/Users/mac/Desktop/work/game-server/venv/lib/python3.11/site-packages/django/middleware/common.py", line 86, in get_full_path_with_slash
    raise RuntimeError(
RuntimeError: You called this URL via POST, but the URL doesn't end in a slash and you have APPEND_SLASH set. Django can't redirect to the slash URL while maintaining POST data. Change your form to point to 127.0.0.1:8000/admin/upload/ (note the trailing slash), or set APPEND_SLASH=False in your Django settings.
[2023-12-28 18:28:58,034][apps.admin.utils.exceptions.op_exception_handler():78] [ERROR] Traceback (most recent call last):
  File "/Users/mac/Desktop/work/game-server/venv/lib/python3.11/site-packages/django/db/backends/utils.py", line 84, in _execute
    return self.cursor.execute(sql, params)
           ^^^^^^^^^^^^^^^^^^^^^^^^^^^^^^^^
  File "/Users/mac/Desktop/work/game-server/venv/lib/python3.11/site-packages/django/db/backends/mysql/base.py", line 71, in execute
    return self.cursor.execute(query, args)
           ^^^^^^^^^^^^^^^^^^^^^^^^^^^^^^^^
  File "/Users/mac/Desktop/work/game-server/venv/lib/python3.11/site-packages/MySQLdb/cursors.py", line 206, in execute
    res = self._query(query)
          ^^^^^^^^^^^^^^^^^^
  File "/Users/mac/Desktop/work/game-server/venv/lib/python3.11/site-packages/MySQLdb/cursors.py", line 319, in _query
    db.query(q)
  File "/Users/mac/Desktop/work/game-server/venv/lib/python3.11/site-packages/MySQLdb/connections.py", line 259, in query
    _mysql.connection.query(self, query)
MySQLdb._exceptions.OperationalError: (1054, "Unknown column 'game_gamecategory.uri' in 'field list'")

The above exception was the direct cause of the following exception:

Traceback (most recent call last):
  File "/Users/mac/Desktop/work/game-server/venv/lib/python3.11/site-packages/rest_framework/views.py", line 506, in dispatch
    response = handler(request, *args, **kwargs)
               ^^^^^^^^^^^^^^^^^^^^^^^^^^^^^^^^^
  File "/usr/local/Cellar/python@3.11/3.11.3/Frameworks/Python.framework/Versions/3.11/lib/python3.11/contextlib.py", line 81, in inner
    return func(*args, **kwds)
           ^^^^^^^^^^^^^^^^^^^
  File "/Users/mac/Desktop/work/game-server/apps/admin/game/views.py", line 27, in add_category
    vipObj = self.queryset.filter(name=jsonData.get('name')).first()
             ^^^^^^^^^^^^^^^^^^^^^^^^^^^^^^^^^^^^^^^^^^^^^^^^^^^^^^^
  File "/Users/mac/Desktop/work/game-server/venv/lib/python3.11/site-packages/django/db/models/query.py", line 653, in first
    for obj in (self if self.ordered else self.order_by('pk'))[:1]:
  File "/Users/mac/Desktop/work/game-server/venv/lib/python3.11/site-packages/django/db/models/query.py", line 274, in __iter__
    self._fetch_all()
  File "/Users/mac/Desktop/work/game-server/venv/lib/python3.11/site-packages/django/db/models/query.py", line 1242, in _fetch_all
    self._result_cache = list(self._iterable_class(self))
                         ^^^^^^^^^^^^^^^^^^^^^^^^^^^^^^^^
  File "/Users/mac/Desktop/work/game-server/venv/lib/python3.11/site-packages/django/db/models/query.py", line 55, in __iter__
    results = compiler.execute_sql(chunked_fetch=self.chunked_fetch, chunk_size=self.chunk_size)
              ^^^^^^^^^^^^^^^^^^^^^^^^^^^^^^^^^^^^^^^^^^^^^^^^^^^^^^^^^^^^^^^^^^^^^^^^^^^^^^^^^^
  File "/Users/mac/Desktop/work/game-server/venv/lib/python3.11/site-packages/django/db/models/sql/compiler.py", line 1142, in execute_sql
    cursor.execute(sql, params)
  File "/Users/mac/Desktop/work/game-server/venv/lib/python3.11/site-packages/django/db/backends/utils.py", line 99, in execute
    return super().execute(sql, params)
           ^^^^^^^^^^^^^^^^^^^^^^^^^^^^
  File "/Users/mac/Desktop/work/game-server/venv/lib/python3.11/site-packages/django/db/backends/utils.py", line 67, in execute
    return self._execute_with_wrappers(sql, params, many=False, executor=self._execute)
           ^^^^^^^^^^^^^^^^^^^^^^^^^^^^^^^^^^^^^^^^^^^^^^^^^^^^^^^^^^^^^^^^^^^^^^^^^^^^
  File "/Users/mac/Desktop/work/game-server/venv/lib/python3.11/site-packages/django/db/backends/utils.py", line 76, in _execute_with_wrappers
    return executor(sql, params, many, context)
           ^^^^^^^^^^^^^^^^^^^^^^^^^^^^^^^^^^^^
  File "/Users/mac/Desktop/work/game-server/venv/lib/python3.11/site-packages/django/db/backends/utils.py", line 80, in _execute
    with self.db.wrap_database_errors:
  File "/Users/mac/Desktop/work/game-server/venv/lib/python3.11/site-packages/django/db/utils.py", line 89, in __exit__
    raise dj_exc_value.with_traceback(traceback) from exc_value
  File "/Users/mac/Desktop/work/game-server/venv/lib/python3.11/site-packages/django/db/backends/utils.py", line 84, in _execute
    return self.cursor.execute(sql, params)
           ^^^^^^^^^^^^^^^^^^^^^^^^^^^^^^^^
  File "/Users/mac/Desktop/work/game-server/venv/lib/python3.11/site-packages/django/db/backends/mysql/base.py", line 71, in execute
    return self.cursor.execute(query, args)
           ^^^^^^^^^^^^^^^^^^^^^^^^^^^^^^^^
  File "/Users/mac/Desktop/work/game-server/venv/lib/python3.11/site-packages/MySQLdb/cursors.py", line 206, in execute
    res = self._query(query)
          ^^^^^^^^^^^^^^^^^^
  File "/Users/mac/Desktop/work/game-server/venv/lib/python3.11/site-packages/MySQLdb/cursors.py", line 319, in _query
    db.query(q)
  File "/Users/mac/Desktop/work/game-server/venv/lib/python3.11/site-packages/MySQLdb/connections.py", line 259, in query
    _mysql.connection.query(self, query)
django.db.utils.OperationalError: (1054, "Unknown column 'game_gamecategory.uri' in 'field list'")

[2023-12-28 18:29:33,459][apps.admin.utils.exceptions.op_exception_handler():78] [ERROR] Traceback (most recent call last):
  File "/Users/mac/Desktop/work/game-server/venv/lib/python3.11/site-packages/django/db/backends/utils.py", line 84, in _execute
    return self.cursor.execute(sql, params)
           ^^^^^^^^^^^^^^^^^^^^^^^^^^^^^^^^
  File "/Users/mac/Desktop/work/game-server/venv/lib/python3.11/site-packages/django/db/backends/mysql/base.py", line 71, in execute
    return self.cursor.execute(query, args)
           ^^^^^^^^^^^^^^^^^^^^^^^^^^^^^^^^
  File "/Users/mac/Desktop/work/game-server/venv/lib/python3.11/site-packages/MySQLdb/cursors.py", line 206, in execute
    res = self._query(query)
          ^^^^^^^^^^^^^^^^^^
  File "/Users/mac/Desktop/work/game-server/venv/lib/python3.11/site-packages/MySQLdb/cursors.py", line 319, in _query
    db.query(q)
  File "/Users/mac/Desktop/work/game-server/venv/lib/python3.11/site-packages/MySQLdb/connections.py", line 259, in query
    _mysql.connection.query(self, query)
MySQLdb._exceptions.OperationalError: (1054, "Unknown column 'game_gamecategory.uri' in 'field list'")

The above exception was the direct cause of the following exception:

Traceback (most recent call last):
  File "/Users/mac/Desktop/work/game-server/venv/lib/python3.11/site-packages/rest_framework/views.py", line 506, in dispatch
    response = handler(request, *args, **kwargs)
               ^^^^^^^^^^^^^^^^^^^^^^^^^^^^^^^^^
  File "/usr/local/Cellar/python@3.11/3.11.3/Frameworks/Python.framework/Versions/3.11/lib/python3.11/contextlib.py", line 81, in inner
    return func(*args, **kwds)
           ^^^^^^^^^^^^^^^^^^^
  File "/Users/mac/Desktop/work/game-server/apps/admin/game/views.py", line 28, in add_category
    vipObj = self.queryset.filter(name=jsonData.get('name')).first()
             ^^^^^^^^^^^^^^^^^^^^^^^^^^^^^^^^^^^^^^^^^^^^^^^^^^^^^^^
  File "/Users/mac/Desktop/work/game-server/venv/lib/python3.11/site-packages/django/db/models/query.py", line 653, in first
    for obj in (self if self.ordered else self.order_by('pk'))[:1]:
  File "/Users/mac/Desktop/work/game-server/venv/lib/python3.11/site-packages/django/db/models/query.py", line 274, in __iter__
    self._fetch_all()
  File "/Users/mac/Desktop/work/game-server/venv/lib/python3.11/site-packages/django/db/models/query.py", line 1242, in _fetch_all
    self._result_cache = list(self._iterable_class(self))
                         ^^^^^^^^^^^^^^^^^^^^^^^^^^^^^^^^
  File "/Users/mac/Desktop/work/game-server/venv/lib/python3.11/site-packages/django/db/models/query.py", line 55, in __iter__
    results = compiler.execute_sql(chunked_fetch=self.chunked_fetch, chunk_size=self.chunk_size)
              ^^^^^^^^^^^^^^^^^^^^^^^^^^^^^^^^^^^^^^^^^^^^^^^^^^^^^^^^^^^^^^^^^^^^^^^^^^^^^^^^^^
  File "/Users/mac/Desktop/work/game-server/venv/lib/python3.11/site-packages/django/db/models/sql/compiler.py", line 1142, in execute_sql
    cursor.execute(sql, params)
  File "/Users/mac/Desktop/work/game-server/venv/lib/python3.11/site-packages/django/db/backends/utils.py", line 99, in execute
    return super().execute(sql, params)
           ^^^^^^^^^^^^^^^^^^^^^^^^^^^^
  File "/Users/mac/Desktop/work/game-server/venv/lib/python3.11/site-packages/django/db/backends/utils.py", line 67, in execute
    return self._execute_with_wrappers(sql, params, many=False, executor=self._execute)
           ^^^^^^^^^^^^^^^^^^^^^^^^^^^^^^^^^^^^^^^^^^^^^^^^^^^^^^^^^^^^^^^^^^^^^^^^^^^^
  File "/Users/mac/Desktop/work/game-server/venv/lib/python3.11/site-packages/django/db/backends/utils.py", line 76, in _execute_with_wrappers
    return executor(sql, params, many, context)
           ^^^^^^^^^^^^^^^^^^^^^^^^^^^^^^^^^^^^
  File "/Users/mac/Desktop/work/game-server/venv/lib/python3.11/site-packages/django/db/backends/utils.py", line 80, in _execute
    with self.db.wrap_database_errors:
  File "/Users/mac/Desktop/work/game-server/venv/lib/python3.11/site-packages/django/db/utils.py", line 89, in __exit__
    raise dj_exc_value.with_traceback(traceback) from exc_value
  File "/Users/mac/Desktop/work/game-server/venv/lib/python3.11/site-packages/django/db/backends/utils.py", line 84, in _execute
    return self.cursor.execute(sql, params)
           ^^^^^^^^^^^^^^^^^^^^^^^^^^^^^^^^
  File "/Users/mac/Desktop/work/game-server/venv/lib/python3.11/site-packages/django/db/backends/mysql/base.py", line 71, in execute
    return self.cursor.execute(query, args)
           ^^^^^^^^^^^^^^^^^^^^^^^^^^^^^^^^
  File "/Users/mac/Desktop/work/game-server/venv/lib/python3.11/site-packages/MySQLdb/cursors.py", line 206, in execute
    res = self._query(query)
          ^^^^^^^^^^^^^^^^^^
  File "/Users/mac/Desktop/work/game-server/venv/lib/python3.11/site-packages/MySQLdb/cursors.py", line 319, in _query
    db.query(q)
  File "/Users/mac/Desktop/work/game-server/venv/lib/python3.11/site-packages/MySQLdb/connections.py", line 259, in query
    _mysql.connection.query(self, query)
django.db.utils.OperationalError: (1054, "Unknown column 'game_gamecategory.uri' in 'field list'")

[2023-12-28 18:32:23,442][apps.admin.utils.exceptions.op_exception_handler():78] [ERROR] Traceback (most recent call last):
  File "/Users/mac/Desktop/work/game-server/venv/lib/python3.11/site-packages/django/db/backends/utils.py", line 84, in _execute
    return self.cursor.execute(sql, params)
           ^^^^^^^^^^^^^^^^^^^^^^^^^^^^^^^^
  File "/Users/mac/Desktop/work/game-server/venv/lib/python3.11/site-packages/django/db/backends/mysql/base.py", line 71, in execute
    return self.cursor.execute(query, args)
           ^^^^^^^^^^^^^^^^^^^^^^^^^^^^^^^^
  File "/Users/mac/Desktop/work/game-server/venv/lib/python3.11/site-packages/MySQLdb/cursors.py", line 206, in execute
    res = self._query(query)
          ^^^^^^^^^^^^^^^^^^
  File "/Users/mac/Desktop/work/game-server/venv/lib/python3.11/site-packages/MySQLdb/cursors.py", line 319, in _query
    db.query(q)
  File "/Users/mac/Desktop/work/game-server/venv/lib/python3.11/site-packages/MySQLdb/connections.py", line 259, in query
    _mysql.connection.query(self, query)
MySQLdb._exceptions.OperationalError: (1054, "Unknown column 'game_gamecategory.uri' in 'field list'")

The above exception was the direct cause of the following exception:

Traceback (most recent call last):
  File "/Users/mac/Desktop/work/game-server/venv/lib/python3.11/site-packages/rest_framework/views.py", line 506, in dispatch
    response = handler(request, *args, **kwargs)
               ^^^^^^^^^^^^^^^^^^^^^^^^^^^^^^^^^
  File "/usr/local/Cellar/python@3.11/3.11.3/Frameworks/Python.framework/Versions/3.11/lib/python3.11/contextlib.py", line 81, in inner
    return func(*args, **kwds)
           ^^^^^^^^^^^^^^^^^^^
  File "/Users/mac/Desktop/work/game-server/apps/admin/game/views.py", line 27, in add_category
    categoryObj = self.queryset.filter(name=jsonData.get('name')).first()
                  ^^^^^^^^^^^^^^^^^^^^^^^^^^^^^^^^^^^^^^^^^^^^^^^^^^^^^^^
  File "/Users/mac/Desktop/work/game-server/venv/lib/python3.11/site-packages/django/db/models/query.py", line 653, in first
    for obj in (self if self.ordered else self.order_by('pk'))[:1]:
  File "/Users/mac/Desktop/work/game-server/venv/lib/python3.11/site-packages/django/db/models/query.py", line 274, in __iter__
    self._fetch_all()
  File "/Users/mac/Desktop/work/game-server/venv/lib/python3.11/site-packages/django/db/models/query.py", line 1242, in _fetch_all
    self._result_cache = list(self._iterable_class(self))
                         ^^^^^^^^^^^^^^^^^^^^^^^^^^^^^^^^
  File "/Users/mac/Desktop/work/game-server/venv/lib/python3.11/site-packages/django/db/models/query.py", line 55, in __iter__
    results = compiler.execute_sql(chunked_fetch=self.chunked_fetch, chunk_size=self.chunk_size)
              ^^^^^^^^^^^^^^^^^^^^^^^^^^^^^^^^^^^^^^^^^^^^^^^^^^^^^^^^^^^^^^^^^^^^^^^^^^^^^^^^^^
  File "/Users/mac/Desktop/work/game-server/venv/lib/python3.11/site-packages/django/db/models/sql/compiler.py", line 1142, in execute_sql
    cursor.execute(sql, params)
  File "/Users/mac/Desktop/work/game-server/venv/lib/python3.11/site-packages/django/db/backends/utils.py", line 99, in execute
    return super().execute(sql, params)
           ^^^^^^^^^^^^^^^^^^^^^^^^^^^^
  File "/Users/mac/Desktop/work/game-server/venv/lib/python3.11/site-packages/django/db/backends/utils.py", line 67, in execute
    return self._execute_with_wrappers(sql, params, many=False, executor=self._execute)
           ^^^^^^^^^^^^^^^^^^^^^^^^^^^^^^^^^^^^^^^^^^^^^^^^^^^^^^^^^^^^^^^^^^^^^^^^^^^^
  File "/Users/mac/Desktop/work/game-server/venv/lib/python3.11/site-packages/django/db/backends/utils.py", line 76, in _execute_with_wrappers
    return executor(sql, params, many, context)
           ^^^^^^^^^^^^^^^^^^^^^^^^^^^^^^^^^^^^
  File "/Users/mac/Desktop/work/game-server/venv/lib/python3.11/site-packages/django/db/backends/utils.py", line 80, in _execute
    with self.db.wrap_database_errors:
  File "/Users/mac/Desktop/work/game-server/venv/lib/python3.11/site-packages/django/db/utils.py", line 89, in __exit__
    raise dj_exc_value.with_traceback(traceback) from exc_value
  File "/Users/mac/Desktop/work/game-server/venv/lib/python3.11/site-packages/django/db/backends/utils.py", line 84, in _execute
    return self.cursor.execute(sql, params)
           ^^^^^^^^^^^^^^^^^^^^^^^^^^^^^^^^
  File "/Users/mac/Desktop/work/game-server/venv/lib/python3.11/site-packages/django/db/backends/mysql/base.py", line 71, in execute
    return self.cursor.execute(query, args)
           ^^^^^^^^^^^^^^^^^^^^^^^^^^^^^^^^
  File "/Users/mac/Desktop/work/game-server/venv/lib/python3.11/site-packages/MySQLdb/cursors.py", line 206, in execute
    res = self._query(query)
          ^^^^^^^^^^^^^^^^^^
  File "/Users/mac/Desktop/work/game-server/venv/lib/python3.11/site-packages/MySQLdb/cursors.py", line 319, in _query
    db.query(q)
  File "/Users/mac/Desktop/work/game-server/venv/lib/python3.11/site-packages/MySQLdb/connections.py", line 259, in query
    _mysql.connection.query(self, query)
django.db.utils.OperationalError: (1054, "Unknown column 'game_gamecategory.uri' in 'field list'")

[2023-12-28 20:43:06,947][apps.admin.utils.exceptions.op_exception_handler():78] [ERROR] Traceback (most recent call last):
  File "/Users/mac/Desktop/work/game-server/venv/lib/python3.11/site-packages/rest_framework/views.py", line 506, in dispatch
    response = handler(request, *args, **kwargs)
               ^^^^^^^^^^^^^^^^^^^^^^^^^^^^^^^^^
  File "/Users/mac/Desktop/work/game-server/apps/admin/game/views.py", line 132, in get_all_category
    print(GameCategory.objects.values_list('id', 'name', flat=True))
          ^^^^^^^^^^^^^^^^^^^^^^^^^^^^^^^^^^^^^^^^^^^^^^^^^^^^^^^^^
  File "/Users/mac/Desktop/work/game-server/venv/lib/python3.11/site-packages/django/db/models/manager.py", line 82, in manager_method
    return getattr(self.get_queryset(), name)(*args, **kwargs)
           ^^^^^^^^^^^^^^^^^^^^^^^^^^^^^^^^^^^^^^^^^^^^^^^^^^^
  File "/Users/mac/Desktop/work/game-server/venv/lib/python3.11/site-packages/django/db/models/query.py", line 806, in values_list
    raise TypeError("'flat' is not valid when values_list is called with more than one field.")
TypeError: 'flat' is not valid when values_list is called with more than one field.

[2023-12-28 20:44:15,504][apps.admin.utils.exceptions.op_exception_handler():78] [ERROR] Traceback (most recent call last):
  File "/Users/mac/Desktop/work/game-server/venv/lib/python3.11/site-packages/rest_framework/views.py", line 506, in dispatch
    response = handler(request, *args, **kwargs)
               ^^^^^^^^^^^^^^^^^^^^^^^^^^^^^^^^^
  File "/Users/mac/Desktop/work/game-server/apps/admin/game/views.py", line 132, in get_all_category
    print(GameCategory.objects.values_list('id', 'name', flat=True))
          ^^^^^^^^^^^^^^^^^^^^^^^^^^^^^^^^^^^^^^^^^^^^^^^^^^^^^^^^^
  File "/Users/mac/Desktop/work/game-server/venv/lib/python3.11/site-packages/django/db/models/manager.py", line 82, in manager_method
    return getattr(self.get_queryset(), name)(*args, **kwargs)
           ^^^^^^^^^^^^^^^^^^^^^^^^^^^^^^^^^^^^^^^^^^^^^^^^^^^
  File "/Users/mac/Desktop/work/game-server/venv/lib/python3.11/site-packages/django/db/models/query.py", line 806, in values_list
    raise TypeError("'flat' is not valid when values_list is called with more than one field.")
TypeError: 'flat' is not valid when values_list is called with more than one field.

[2023-12-28 21:01:54,967][apps.admin.utils.exceptions.op_exception_handler():78] [ERROR] Traceback (most recent call last):
  File "/Users/mac/Desktop/work/game-server/venv/lib/python3.11/site-packages/rest_framework/views.py", line 506, in dispatch
    response = handler(request, *args, **kwargs)
               ^^^^^^^^^^^^^^^^^^^^^^^^^^^^^^^^^
  File "/usr/local/Cellar/python@3.11/3.11.3/Frameworks/Python.framework/Versions/3.11/lib/python3.11/contextlib.py", line 81, in inner
    return func(*args, **kwds)
           ^^^^^^^^^^^^^^^^^^^
  File "/Users/mac/Desktop/work/game-server/apps/admin/game/views.py", line 92, in add_manufacturer
    serializer.save()
  File "/Users/mac/Desktop/work/game-server/apps/admin/op_drf/serializers.py", line 34, in save
    return super().save(**kwargs)
           ^^^^^^^^^^^^^^^^^^^^^^
  File "/Users/mac/Desktop/work/game-server/venv/lib/python3.11/site-packages/rest_framework/serializers.py", line 205, in save
    self.instance = self.create(validated_data)
                    ^^^^^^^^^^^^^^^^^^^^^^^^^^^
  File "/Users/mac/Desktop/work/game-server/apps/admin/op_drf/serializers.py", line 47, in create
    return super().create(validated_data)
           ^^^^^^^^^^^^^^^^^^^^^^^^^^^^^^
  File "/Users/mac/Desktop/work/game-server/venv/lib/python3.11/site-packages/rest_framework/serializers.py", line 939, in create
    instance = ModelClass._default_manager.create(**validated_data)
               ^^^^^^^^^^^^^^^^^^^^^^^^^^^^^^^^^^^^^^^^^^^^^^^^^^^^
  File "/Users/mac/Desktop/work/game-server/venv/lib/python3.11/site-packages/django/db/models/manager.py", line 82, in manager_method
    return getattr(self.get_queryset(), name)(*args, **kwargs)
           ^^^^^^^^^^^^^^^^^^^^^^^^^^^^^^^^^^^^^^^^^^^^^^^^^^^
  File "/Users/mac/Desktop/work/game-server/venv/lib/python3.11/site-packages/django/db/models/query.py", line 420, in create
    obj = self.model(**kwargs)
          ^^^^^^^^^^^^^^^^^^^^
  File "/Users/mac/Desktop/work/game-server/venv/lib/python3.11/site-packages/django/db/models/base.py", line 483, in __init__
    _setattr(self, field.name, rel_obj)
  File "/Users/mac/Desktop/work/game-server/venv/lib/python3.11/site-packages/django/db/models/fields/related_descriptors.py", line 206, in __set__
    raise ValueError(
ValueError: Cannot assign "'6'": "GameManufacturer.gameCategory" must be a "GameCategory" instance.

[2023-12-28 21:03:05,459][apps.admin.utils.exceptions.op_exception_handler():78] [ERROR] Traceback (most recent call last):
  File "/Users/mac/Desktop/work/game-server/venv/lib/python3.11/site-packages/rest_framework/views.py", line 506, in dispatch
    response = handler(request, *args, **kwargs)
               ^^^^^^^^^^^^^^^^^^^^^^^^^^^^^^^^^
  File "/usr/local/Cellar/python@3.11/3.11.3/Frameworks/Python.framework/Versions/3.11/lib/python3.11/contextlib.py", line 81, in inner
    return func(*args, **kwds)
           ^^^^^^^^^^^^^^^^^^^
  File "/Users/mac/Desktop/work/game-server/apps/admin/game/views.py", line 92, in add_manufacturer
    serializer.save()
  File "/Users/mac/Desktop/work/game-server/apps/admin/op_drf/serializers.py", line 34, in save
    return super().save(**kwargs)
           ^^^^^^^^^^^^^^^^^^^^^^
  File "/Users/mac/Desktop/work/game-server/venv/lib/python3.11/site-packages/rest_framework/serializers.py", line 205, in save
    self.instance = self.create(validated_data)
                    ^^^^^^^^^^^^^^^^^^^^^^^^^^^
  File "/Users/mac/Desktop/work/game-server/apps/admin/op_drf/serializers.py", line 47, in create
    return super().create(validated_data)
           ^^^^^^^^^^^^^^^^^^^^^^^^^^^^^^
  File "/Users/mac/Desktop/work/game-server/venv/lib/python3.11/site-packages/rest_framework/serializers.py", line 939, in create
    instance = ModelClass._default_manager.create(**validated_data)
               ^^^^^^^^^^^^^^^^^^^^^^^^^^^^^^^^^^^^^^^^^^^^^^^^^^^^
  File "/Users/mac/Desktop/work/game-server/venv/lib/python3.11/site-packages/django/db/models/manager.py", line 82, in manager_method
    return getattr(self.get_queryset(), name)(*args, **kwargs)
           ^^^^^^^^^^^^^^^^^^^^^^^^^^^^^^^^^^^^^^^^^^^^^^^^^^^
  File "/Users/mac/Desktop/work/game-server/venv/lib/python3.11/site-packages/django/db/models/query.py", line 420, in create
    obj = self.model(**kwargs)
          ^^^^^^^^^^^^^^^^^^^^
  File "/Users/mac/Desktop/work/game-server/venv/lib/python3.11/site-packages/django/db/models/base.py", line 483, in __init__
    _setattr(self, field.name, rel_obj)
  File "/Users/mac/Desktop/work/game-server/venv/lib/python3.11/site-packages/django/db/models/fields/related_descriptors.py", line 206, in __set__
    raise ValueError(
ValueError: Cannot assign "'6'": "GameManufacturer.gameCategory" must be a "GameCategory" instance.

[2023-12-28 21:18:22,050][apps.admin.utils.exceptions.op_exception_handler():78] [ERROR] Traceback (most recent call last):
  File "/Users/mac/Desktop/work/game-server/venv/lib/python3.11/site-packages/rest_framework/views.py", line 506, in dispatch
    response = handler(request, *args, **kwargs)
               ^^^^^^^^^^^^^^^^^^^^^^^^^^^^^^^^^
  File "/usr/local/Cellar/python@3.11/3.11.3/Frameworks/Python.framework/Versions/3.11/lib/python3.11/contextlib.py", line 81, in inner
    return func(*args, **kwds)
           ^^^^^^^^^^^^^^^^^^^
  File "/Users/mac/Desktop/work/game-server/apps/admin/game/views.py", line 93, in add_manufacturer
    serializer.save()
  File "/Users/mac/Desktop/work/game-server/apps/admin/op_drf/serializers.py", line 34, in save
    return super().save(**kwargs)
           ^^^^^^^^^^^^^^^^^^^^^^
  File "/Users/mac/Desktop/work/game-server/venv/lib/python3.11/site-packages/rest_framework/serializers.py", line 205, in save
    self.instance = self.create(validated_data)
                    ^^^^^^^^^^^^^^^^^^^^^^^^^^^
  File "/Users/mac/Desktop/work/game-server/apps/admin/op_drf/serializers.py", line 47, in create
    return super().create(validated_data)
           ^^^^^^^^^^^^^^^^^^^^^^^^^^^^^^
  File "/Users/mac/Desktop/work/game-server/venv/lib/python3.11/site-packages/rest_framework/serializers.py", line 939, in create
    instance = ModelClass._default_manager.create(**validated_data)
               ^^^^^^^^^^^^^^^^^^^^^^^^^^^^^^^^^^^^^^^^^^^^^^^^^^^^
  File "/Users/mac/Desktop/work/game-server/venv/lib/python3.11/site-packages/django/db/models/manager.py", line 82, in manager_method
    return getattr(self.get_queryset(), name)(*args, **kwargs)
           ^^^^^^^^^^^^^^^^^^^^^^^^^^^^^^^^^^^^^^^^^^^^^^^^^^^
  File "/Users/mac/Desktop/work/game-server/venv/lib/python3.11/site-packages/django/db/models/query.py", line 420, in create
    obj = self.model(**kwargs)
          ^^^^^^^^^^^^^^^^^^^^
  File "/Users/mac/Desktop/work/game-server/venv/lib/python3.11/site-packages/django/db/models/base.py", line 483, in __init__
    _setattr(self, field.name, rel_obj)
  File "/Users/mac/Desktop/work/game-server/venv/lib/python3.11/site-packages/django/db/models/fields/related_descriptors.py", line 206, in __set__
    raise ValueError(
ValueError: Cannot assign "'6'": "GameManufacturer.gameCategory" must be a "GameCategory" instance.

[2023-12-28 21:28:21,495][apps.admin.utils.exceptions.op_exception_handler():78] [ERROR] Traceback (most recent call last):
  File "/Users/mac/Desktop/work/game-server/venv/lib/python3.11/site-packages/rest_framework/views.py", line 506, in dispatch
    response = handler(request, *args, **kwargs)
               ^^^^^^^^^^^^^^^^^^^^^^^^^^^^^^^^^
  File "/usr/local/Cellar/python@3.11/3.11.3/Frameworks/Python.framework/Versions/3.11/lib/python3.11/contextlib.py", line 81, in inner
    return func(*args, **kwds)
           ^^^^^^^^^^^^^^^^^^^
  File "/Users/mac/Desktop/work/game-server/apps/admin/game/views.py", line 92, in add_manufacturer
    serializer.save()
  File "/Users/mac/Desktop/work/game-server/apps/admin/op_drf/serializers.py", line 34, in save
    return super().save(**kwargs)
           ^^^^^^^^^^^^^^^^^^^^^^
  File "/Users/mac/Desktop/work/game-server/venv/lib/python3.11/site-packages/rest_framework/serializers.py", line 205, in save
    self.instance = self.create(validated_data)
                    ^^^^^^^^^^^^^^^^^^^^^^^^^^^
  File "/Users/mac/Desktop/work/game-server/apps/admin/op_drf/serializers.py", line 47, in create
    return super().create(validated_data)
           ^^^^^^^^^^^^^^^^^^^^^^^^^^^^^^
  File "/Users/mac/Desktop/work/game-server/venv/lib/python3.11/site-packages/rest_framework/serializers.py", line 939, in create
    instance = ModelClass._default_manager.create(**validated_data)
               ^^^^^^^^^^^^^^^^^^^^^^^^^^^^^^^^^^^^^^^^^^^^^^^^^^^^
  File "/Users/mac/Desktop/work/game-server/venv/lib/python3.11/site-packages/django/db/models/manager.py", line 82, in manager_method
    return getattr(self.get_queryset(), name)(*args, **kwargs)
           ^^^^^^^^^^^^^^^^^^^^^^^^^^^^^^^^^^^^^^^^^^^^^^^^^^^
  File "/Users/mac/Desktop/work/game-server/venv/lib/python3.11/site-packages/django/db/models/query.py", line 420, in create
    obj = self.model(**kwargs)
          ^^^^^^^^^^^^^^^^^^^^
  File "/Users/mac/Desktop/work/game-server/venv/lib/python3.11/site-packages/django/db/models/base.py", line 483, in __init__
    _setattr(self, field.name, rel_obj)
  File "/Users/mac/Desktop/work/game-server/venv/lib/python3.11/site-packages/django/db/models/fields/related_descriptors.py", line 206, in __set__
    raise ValueError(
ValueError: Cannot assign "'3'": "GameManufacturer.gameCategory" must be a "GameCategory" instance.

[2023-12-28 21:34:17,169][apps.admin.utils.exceptions.op_exception_handler():78] [ERROR] Traceback (most recent call last):
  File "/Users/mac/Desktop/work/game-server/venv/lib/python3.11/site-packages/rest_framework/views.py", line 506, in dispatch
    response = handler(request, *args, **kwargs)
               ^^^^^^^^^^^^^^^^^^^^^^^^^^^^^^^^^
  File "/usr/local/Cellar/python@3.11/3.11.3/Frameworks/Python.framework/Versions/3.11/lib/python3.11/contextlib.py", line 81, in inner
    return func(*args, **kwds)
           ^^^^^^^^^^^^^^^^^^^
  File "/Users/mac/Desktop/work/game-server/apps/admin/game/views.py", line 93, in add_manufacturer
    serializer.save()
  File "/Users/mac/Desktop/work/game-server/apps/admin/op_drf/serializers.py", line 34, in save
    return super().save(**kwargs)
           ^^^^^^^^^^^^^^^^^^^^^^
  File "/Users/mac/Desktop/work/game-server/venv/lib/python3.11/site-packages/rest_framework/serializers.py", line 205, in save
    self.instance = self.create(validated_data)
                    ^^^^^^^^^^^^^^^^^^^^^^^^^^^
  File "/Users/mac/Desktop/work/game-server/apps/admin/op_drf/serializers.py", line 47, in create
    return super().create(validated_data)
           ^^^^^^^^^^^^^^^^^^^^^^^^^^^^^^
  File "/Users/mac/Desktop/work/game-server/venv/lib/python3.11/site-packages/rest_framework/serializers.py", line 939, in create
    instance = ModelClass._default_manager.create(**validated_data)
               ^^^^^^^^^^^^^^^^^^^^^^^^^^^^^^^^^^^^^^^^^^^^^^^^^^^^
  File "/Users/mac/Desktop/work/game-server/venv/lib/python3.11/site-packages/django/db/models/manager.py", line 82, in manager_method
    return getattr(self.get_queryset(), name)(*args, **kwargs)
           ^^^^^^^^^^^^^^^^^^^^^^^^^^^^^^^^^^^^^^^^^^^^^^^^^^^
  File "/Users/mac/Desktop/work/game-server/venv/lib/python3.11/site-packages/django/db/models/query.py", line 420, in create
    obj = self.model(**kwargs)
          ^^^^^^^^^^^^^^^^^^^^
  File "/Users/mac/Desktop/work/game-server/venv/lib/python3.11/site-packages/django/db/models/base.py", line 483, in __init__
    _setattr(self, field.name, rel_obj)
  File "/Users/mac/Desktop/work/game-server/venv/lib/python3.11/site-packages/django/db/models/fields/related_descriptors.py", line 206, in __set__
    raise ValueError(
ValueError: Cannot assign "'3'": "GameManufacturer.gameCategory" must be a "GameCategory" instance.

[2023-12-28 22:20:31,885][apps.admin.utils.exceptions.op_exception_handler():78] [ERROR] Traceback (most recent call last):
  File "/Users/mac/Desktop/work/game-server/venv/lib/python3.11/site-packages/rest_framework/views.py", line 506, in dispatch
    response = handler(request, *args, **kwargs)
               ^^^^^^^^^^^^^^^^^^^^^^^^^^^^^^^^^
  File "/usr/local/Cellar/python@3.11/3.11.3/Frameworks/Python.framework/Versions/3.11/lib/python3.11/contextlib.py", line 81, in inner
    return func(*args, **kwds)
           ^^^^^^^^^^^^^^^^^^^
  File "/Users/mac/Desktop/work/game-server/apps/admin/game/views.py", line 91, in add_manufacturer
    if serializer.is_valid(raise_exception=True):
       ^^^^^^^^^^^^^^^^^^^^^^^^^^^^^^^^^^^^^^^^^
  File "/Users/mac/Desktop/work/game-server/venv/lib/python3.11/site-packages/rest_framework/serializers.py", line 718, in is_valid
    assert hasattr(self, 'initial_data'), (
AssertionError: Cannot call `.is_valid()` as no `data=` keyword argument was passed when instantiating the serializer instance.

[2023-12-29 10:23:09,055][apps.admin.utils.exceptions.op_exception_handler():78] [ERROR] Traceback (most recent call last):
  File "/Users/mac/Desktop/work/game-server/venv/lib/python3.11/site-packages/rest_framework/views.py", line 506, in dispatch
    response = handler(request, *args, **kwargs)
               ^^^^^^^^^^^^^^^^^^^^^^^^^^^^^^^^^
  File "/usr/local/Cellar/python@3.11/3.11.3/Frameworks/Python.framework/Versions/3.11/lib/python3.11/contextlib.py", line 81, in inner
    return func(*args, **kwds)
           ^^^^^^^^^^^^^^^^^^^
  File "/Users/mac/Desktop/work/game-server/apps/admin/game/views.py", line 92, in add_manufacturer
    serializer.save()
  File "/Users/mac/Desktop/work/game-server/apps/admin/op_drf/serializers.py", line 34, in save
    return super().save(**kwargs)
           ^^^^^^^^^^^^^^^^^^^^^^
  File "/Users/mac/Desktop/work/game-server/venv/lib/python3.11/site-packages/rest_framework/serializers.py", line 205, in save
    self.instance = self.create(validated_data)
                    ^^^^^^^^^^^^^^^^^^^^^^^^^^^
  File "/Users/mac/Desktop/work/game-server/apps/admin/op_drf/serializers.py", line 47, in create
    return super().create(validated_data)
           ^^^^^^^^^^^^^^^^^^^^^^^^^^^^^^
  File "/Users/mac/Desktop/work/game-server/venv/lib/python3.11/site-packages/rest_framework/serializers.py", line 939, in create
    instance = ModelClass._default_manager.create(**validated_data)
               ^^^^^^^^^^^^^^^^^^^^^^^^^^^^^^^^^^^^^^^^^^^^^^^^^^^^
  File "/Users/mac/Desktop/work/game-server/venv/lib/python3.11/site-packages/django/db/models/manager.py", line 82, in manager_method
    return getattr(self.get_queryset(), name)(*args, **kwargs)
           ^^^^^^^^^^^^^^^^^^^^^^^^^^^^^^^^^^^^^^^^^^^^^^^^^^^
  File "/Users/mac/Desktop/work/game-server/venv/lib/python3.11/site-packages/django/db/models/query.py", line 420, in create
    obj = self.model(**kwargs)
          ^^^^^^^^^^^^^^^^^^^^
  File "/Users/mac/Desktop/work/game-server/venv/lib/python3.11/site-packages/django/db/models/base.py", line 483, in __init__
    _setattr(self, field.name, rel_obj)
  File "/Users/mac/Desktop/work/game-server/venv/lib/python3.11/site-packages/django/db/models/fields/related_descriptors.py", line 206, in __set__
    raise ValueError(
ValueError: Cannot assign "'3'": "GameManufacturer.gameCategory" must be a "GameCategory" instance.

[2023-12-29 10:25:17,008][apps.admin.utils.exceptions.op_exception_handler():78] [ERROR] Traceback (most recent call last):
  File "/Users/mac/Desktop/work/game-server/venv/lib/python3.11/site-packages/rest_framework/views.py", line 506, in dispatch
    response = handler(request, *args, **kwargs)
               ^^^^^^^^^^^^^^^^^^^^^^^^^^^^^^^^^
  File "/usr/local/Cellar/python@3.11/3.11.3/Frameworks/Python.framework/Versions/3.11/lib/python3.11/contextlib.py", line 81, in inner
    return func(*args, **kwds)
           ^^^^^^^^^^^^^^^^^^^
  File "/Users/mac/Desktop/work/game-server/apps/admin/game/views.py", line 94, in add_manufacturer
    instance.gameCategory_id = jsonData.get('gameCategory')
    ^^^^^^^^^^^^^^^^^^^^^^^^
AttributeError: 'int' object has no attribute 'gameCategory_id'

[2023-12-29 10:25:44,754][apps.admin.utils.exceptions.op_exception_handler():78] [ERROR] Traceback (most recent call last):
  File "/Users/mac/Desktop/work/game-server/venv/lib/python3.11/site-packages/rest_framework/views.py", line 506, in dispatch
    response = handler(request, *args, **kwargs)
               ^^^^^^^^^^^^^^^^^^^^^^^^^^^^^^^^^
  File "/usr/local/Cellar/python@3.11/3.11.3/Frameworks/Python.framework/Versions/3.11/lib/python3.11/contextlib.py", line 81, in inner
    return func(*args, **kwds)
           ^^^^^^^^^^^^^^^^^^^
  File "/Users/mac/Desktop/work/game-server/apps/admin/game/views.py", line 95, in add_manufacturer
    instance.gameCategory_id = jsonData.get('gameCategory')
    ^^^^^^^^^^^^^^^^^^^^^^^^
AttributeError: 'int' object has no attribute 'gameCategory_id'

[2023-12-29 10:47:06,445][apps.admin.utils.exceptions.op_exception_handler():78] [ERROR] Traceback (most recent call last):
  File "/Users/mac/Desktop/work/game-server/venv/lib/python3.11/site-packages/rest_framework/views.py", line 506, in dispatch
    response = handler(request, *args, **kwargs)
               ^^^^^^^^^^^^^^^^^^^^^^^^^^^^^^^^^
  File "/Users/mac/Desktop/work/game-server/apps/admin/op_drf/mixins.py", line 47, in list
    return self.get_paginated_response(serializer.data)
                                       ^^^^^^^^^^^^^^^
  File "/Users/mac/Desktop/work/game-server/venv/lib/python3.11/site-packages/rest_framework/serializers.py", line 745, in data
    ret = super().data
          ^^^^^^^^^^^^
  File "/Users/mac/Desktop/work/game-server/venv/lib/python3.11/site-packages/rest_framework/serializers.py", line 246, in data
    self._data = self.to_representation(self.instance)
                 ^^^^^^^^^^^^^^^^^^^^^^^^^^^^^^^^^^^^^
  File "/Users/mac/Desktop/work/game-server/venv/lib/python3.11/site-packages/rest_framework/serializers.py", line 663, in to_representation
    return [
           ^
  File "/Users/mac/Desktop/work/game-server/venv/lib/python3.11/site-packages/rest_framework/serializers.py", line 664, in <listcomp>
    self.child.to_representation(item) for item in iterable
    ^^^^^^^^^^^^^^^^^^^^^^^^^^^^^^^^^^
  File "/Users/mac/Desktop/work/game-server/venv/lib/python3.11/site-packages/rest_framework/serializers.py", line 515, in to_representation
    ret[field.field_name] = field.to_representation(attribute)
                            ^^^^^^^^^^^^^^^^^^^^^^^^^^^^^^^^^^
  File "/Users/mac/Desktop/work/game-server/venv/lib/python3.11/site-packages/rest_framework/fields.py", line 963, in to_representation
    return int(value)
           ^^^^^^^^^^
TypeError: int() argument must be a string, a bytes-like object or a real number, not 'GameCategory'

[2023-12-29 10:55:32,672][apps.admin.utils.exceptions.op_exception_handler():78] [ERROR] Traceback (most recent call last):
  File "/Users/mac/Desktop/work/game-server/venv/lib/python3.11/site-packages/rest_framework/views.py", line 506, in dispatch
    response = handler(request, *args, **kwargs)
               ^^^^^^^^^^^^^^^^^^^^^^^^^^^^^^^^^
  File "/Users/mac/Desktop/work/game-server/apps/admin/op_drf/mixins.py", line 47, in list
    return self.get_paginated_response(serializer.data)
                                       ^^^^^^^^^^^^^^^
  File "/Users/mac/Desktop/work/game-server/venv/lib/python3.11/site-packages/rest_framework/serializers.py", line 745, in data
    ret = super().data
          ^^^^^^^^^^^^
  File "/Users/mac/Desktop/work/game-server/venv/lib/python3.11/site-packages/rest_framework/serializers.py", line 246, in data
    self._data = self.to_representation(self.instance)
                 ^^^^^^^^^^^^^^^^^^^^^^^^^^^^^^^^^^^^^
  File "/Users/mac/Desktop/work/game-server/venv/lib/python3.11/site-packages/rest_framework/serializers.py", line 663, in to_representation
    return [
           ^
  File "/Users/mac/Desktop/work/game-server/venv/lib/python3.11/site-packages/rest_framework/serializers.py", line 664, in <listcomp>
    self.child.to_representation(item) for item in iterable
    ^^^^^^^^^^^^^^^^^^^^^^^^^^^^^^^^^^
  File "/Users/mac/Desktop/work/game-server/venv/lib/python3.11/site-packages/rest_framework/serializers.py", line 515, in to_representation
    ret[field.field_name] = field.to_representation(attribute)
                            ^^^^^^^^^^^^^^^^^^^^^^^^^^^^^^^^^^
  File "/Users/mac/Desktop/work/game-server/venv/lib/python3.11/site-packages/rest_framework/fields.py", line 963, in to_representation
    return int(value)
           ^^^^^^^^^^
TypeError: int() argument must be a string, a bytes-like object or a real number, not 'GameCategory'

[2023-12-29 10:57:19,227][apps.admin.utils.exceptions.op_exception_handler():78] [ERROR] Traceback (most recent call last):
  File "/Users/mac/Desktop/work/game-server/venv/lib/python3.11/site-packages/rest_framework/views.py", line 506, in dispatch
    response = handler(request, *args, **kwargs)
               ^^^^^^^^^^^^^^^^^^^^^^^^^^^^^^^^^
  File "/Users/mac/Desktop/work/game-server/apps/admin/op_drf/mixins.py", line 47, in list
    return self.get_paginated_response(serializer.data)
                                       ^^^^^^^^^^^^^^^
  File "/Users/mac/Desktop/work/game-server/venv/lib/python3.11/site-packages/rest_framework/serializers.py", line 745, in data
    ret = super().data
          ^^^^^^^^^^^^
  File "/Users/mac/Desktop/work/game-server/venv/lib/python3.11/site-packages/rest_framework/serializers.py", line 246, in data
    self._data = self.to_representation(self.instance)
                 ^^^^^^^^^^^^^^^^^^^^^^^^^^^^^^^^^^^^^
  File "/Users/mac/Desktop/work/game-server/venv/lib/python3.11/site-packages/rest_framework/serializers.py", line 663, in to_representation
    return [
           ^
  File "/Users/mac/Desktop/work/game-server/venv/lib/python3.11/site-packages/rest_framework/serializers.py", line 664, in <listcomp>
    self.child.to_representation(item) for item in iterable
    ^^^^^^^^^^^^^^^^^^^^^^^^^^^^^^^^^^
  File "/Users/mac/Desktop/work/game-server/venv/lib/python3.11/site-packages/rest_framework/serializers.py", line 500, in to_representation
    for field in fields:
  File "/Users/mac/Desktop/work/game-server/venv/lib/python3.11/site-packages/rest_framework/serializers.py", line 361, in _readable_fields
    for field in self.fields.values():
                 ^^^^^^^^^^^
  File "/Users/mac/Desktop/work/game-server/venv/lib/python3.11/site-packages/django/utils/functional.py", line 80, in __get__
    res = instance.__dict__[self.name] = self.func(instance)
                                         ^^^^^^^^^^^^^^^^^^^
  File "/Users/mac/Desktop/work/game-server/apps/admin/op_drf/serializers.py", line 63, in fields
    for key, value in self.get_fields().items():
                      ^^^^^^^^^^^^^^^^^
  File "/Users/mac/Desktop/work/game-server/venv/lib/python3.11/site-packages/rest_framework/serializers.py", line 1034, in get_fields
    extra_kwargs, hidden_fields = self.get_uniqueness_extra_kwargs(
                                  ^^^^^^^^^^^^^^^^^^^^^^^^^^^^^^^^^
  File "/Users/mac/Desktop/work/game-server/venv/lib/python3.11/site-packages/rest_framework/serializers.py", line 1389, in get_uniqueness_extra_kwargs
    model_fields = self._get_model_fields(
                   ^^^^^^^^^^^^^^^^^^^^^^^
  File "/Users/mac/Desktop/work/game-server/venv/lib/python3.11/site-packages/rest_framework/serializers.py", line 1478, in _get_model_fields
    field = model._meta.get_field(source)
            ^^^^^^^^^^^^^^^^^^^^^^^^^^^^^
  File "/Users/mac/Desktop/work/game-server/venv/lib/python3.11/site-packages/django/db/models/options.py", line 551, in get_field
    return self._forward_fields_map[field_name]
           ~~~~~~~~~~~~~~~~~~~~~~~~^^^^^^^^^^^^
TypeError: unhashable type: 'dict'

[2023-12-29 11:11:15,643][apps.admin.utils.exceptions.op_exception_handler():78] [ERROR] Traceback (most recent call last):
  File "/Users/mac/Desktop/work/game-server/venv/lib/python3.11/site-packages/rest_framework/views.py", line 506, in dispatch
    response = handler(request, *args, **kwargs)
               ^^^^^^^^^^^^^^^^^^^^^^^^^^^^^^^^^
  File "/Users/mac/Desktop/work/game-server/apps/admin/op_drf/mixins.py", line 47, in list
    return self.get_paginated_response(serializer.data)
                                       ^^^^^^^^^^^^^^^
  File "/Users/mac/Desktop/work/game-server/venv/lib/python3.11/site-packages/rest_framework/serializers.py", line 745, in data
    ret = super().data
          ^^^^^^^^^^^^
  File "/Users/mac/Desktop/work/game-server/venv/lib/python3.11/site-packages/rest_framework/serializers.py", line 246, in data
    self._data = self.to_representation(self.instance)
                 ^^^^^^^^^^^^^^^^^^^^^^^^^^^^^^^^^^^^^
  File "/Users/mac/Desktop/work/game-server/venv/lib/python3.11/site-packages/rest_framework/serializers.py", line 663, in to_representation
    return [
           ^
  File "/Users/mac/Desktop/work/game-server/venv/lib/python3.11/site-packages/rest_framework/serializers.py", line 664, in <listcomp>
    self.child.to_representation(item) for item in iterable
    ^^^^^^^^^^^^^^^^^^^^^^^^^^^^^^^^^^
  File "/Users/mac/Desktop/work/game-server/venv/lib/python3.11/site-packages/rest_framework/serializers.py", line 515, in to_representation
    ret[field.field_name] = field.to_representation(attribute)
                            ^^^^^^^^^^^^^^^^^^^^^^^^^^^^^^^^^^
  File "/Users/mac/Desktop/work/game-server/venv/lib/python3.11/site-packages/rest_framework/serializers.py", line 663, in to_representation
    return [
           ^
TypeError: 'GameCategory' object is not iterable

[2023-12-29 11:19:15,489][apps.admin.utils.exceptions.op_exception_handler():78] [ERROR] Traceback (most recent call last):
  File "/Users/mac/Desktop/work/game-server/venv/lib/python3.11/site-packages/rest_framework/views.py", line 506, in dispatch
    response = handler(request, *args, **kwargs)
               ^^^^^^^^^^^^^^^^^^^^^^^^^^^^^^^^^
  File "/usr/local/Cellar/python@3.11/3.11.3/Frameworks/Python.framework/Versions/3.11/lib/python3.11/contextlib.py", line 81, in inner
    return func(*args, **kwds)
           ^^^^^^^^^^^^^^^^^^^
  File "/Users/mac/Desktop/work/game-server/apps/admin/game/views.py", line 92, in add_manufacturer
    serializer.save()
  File "/Users/mac/Desktop/work/game-server/apps/admin/op_drf/serializers.py", line 34, in save
    return super().save(**kwargs)
           ^^^^^^^^^^^^^^^^^^^^^^
  File "/Users/mac/Desktop/work/game-server/venv/lib/python3.11/site-packages/rest_framework/serializers.py", line 205, in save
    self.instance = self.create(validated_data)
                    ^^^^^^^^^^^^^^^^^^^^^^^^^^^
  File "/Users/mac/Desktop/work/game-server/apps/admin/op_drf/serializers.py", line 47, in create
    return super().create(validated_data)
           ^^^^^^^^^^^^^^^^^^^^^^^^^^^^^^
  File "/Users/mac/Desktop/work/game-server/venv/lib/python3.11/site-packages/rest_framework/serializers.py", line 939, in create
    instance = ModelClass._default_manager.create(**validated_data)
               ^^^^^^^^^^^^^^^^^^^^^^^^^^^^^^^^^^^^^^^^^^^^^^^^^^^^
  File "/Users/mac/Desktop/work/game-server/venv/lib/python3.11/site-packages/django/db/models/manager.py", line 82, in manager_method
    return getattr(self.get_queryset(), name)(*args, **kwargs)
           ^^^^^^^^^^^^^^^^^^^^^^^^^^^^^^^^^^^^^^^^^^^^^^^^^^^
  File "/Users/mac/Desktop/work/game-server/venv/lib/python3.11/site-packages/django/db/models/query.py", line 420, in create
    obj = self.model(**kwargs)
          ^^^^^^^^^^^^^^^^^^^^
  File "/Users/mac/Desktop/work/game-server/venv/lib/python3.11/site-packages/django/db/models/base.py", line 483, in __init__
    _setattr(self, field.name, rel_obj)
  File "/Users/mac/Desktop/work/game-server/venv/lib/python3.11/site-packages/django/db/models/fields/related_descriptors.py", line 206, in __set__
    raise ValueError(
ValueError: Cannot assign "3": "GameManufacturer.gameCategory" must be a "GameCategory" instance.

[2023-12-29 11:20:54,959][apps.admin.utils.exceptions.op_exception_handler():78] [ERROR] Traceback (most recent call last):
  File "/Users/mac/Desktop/work/game-server/venv/lib/python3.11/site-packages/rest_framework/views.py", line 506, in dispatch
    response = handler(request, *args, **kwargs)
               ^^^^^^^^^^^^^^^^^^^^^^^^^^^^^^^^^
  File "/usr/local/Cellar/python@3.11/3.11.3/Frameworks/Python.framework/Versions/3.11/lib/python3.11/contextlib.py", line 81, in inner
    return func(*args, **kwds)
           ^^^^^^^^^^^^^^^^^^^
  File "/Users/mac/Desktop/work/game-server/apps/admin/game/views.py", line 92, in add_manufacturer
    serializer.save()
  File "/Users/mac/Desktop/work/game-server/apps/admin/op_drf/serializers.py", line 34, in save
    return super().save(**kwargs)
           ^^^^^^^^^^^^^^^^^^^^^^
  File "/Users/mac/Desktop/work/game-server/venv/lib/python3.11/site-packages/rest_framework/serializers.py", line 205, in save
    self.instance = self.create(validated_data)
                    ^^^^^^^^^^^^^^^^^^^^^^^^^^^
  File "/Users/mac/Desktop/work/game-server/apps/admin/op_drf/serializers.py", line 47, in create
    return super().create(validated_data)
           ^^^^^^^^^^^^^^^^^^^^^^^^^^^^^^
  File "/Users/mac/Desktop/work/game-server/venv/lib/python3.11/site-packages/rest_framework/serializers.py", line 939, in create
    instance = ModelClass._default_manager.create(**validated_data)
               ^^^^^^^^^^^^^^^^^^^^^^^^^^^^^^^^^^^^^^^^^^^^^^^^^^^^
  File "/Users/mac/Desktop/work/game-server/venv/lib/python3.11/site-packages/django/db/models/manager.py", line 82, in manager_method
    return getattr(self.get_queryset(), name)(*args, **kwargs)
           ^^^^^^^^^^^^^^^^^^^^^^^^^^^^^^^^^^^^^^^^^^^^^^^^^^^
  File "/Users/mac/Desktop/work/game-server/venv/lib/python3.11/site-packages/django/db/models/query.py", line 420, in create
    obj = self.model(**kwargs)
          ^^^^^^^^^^^^^^^^^^^^
  File "/Users/mac/Desktop/work/game-server/venv/lib/python3.11/site-packages/django/db/models/base.py", line 483, in __init__
    _setattr(self, field.name, rel_obj)
  File "/Users/mac/Desktop/work/game-server/venv/lib/python3.11/site-packages/django/db/models/fields/related_descriptors.py", line 206, in __set__
    raise ValueError(
ValueError: Cannot assign "3": "GameManufacturer.gameCategory" must be a "GameCategory" instance.

[2023-12-29 11:42:17,407][apps.admin.utils.exceptions.op_exception_handler():78] [ERROR] Traceback (most recent call last):
  File "/Users/mac/Desktop/work/game-server/venv/lib/python3.11/site-packages/rest_framework/views.py", line 506, in dispatch
    response = handler(request, *args, **kwargs)
               ^^^^^^^^^^^^^^^^^^^^^^^^^^^^^^^^^
  File "/Users/mac/Desktop/work/game-server/apps/admin/op_drf/mixins.py", line 47, in list
    return self.get_paginated_response(serializer.data)
                                       ^^^^^^^^^^^^^^^
  File "/Users/mac/Desktop/work/game-server/venv/lib/python3.11/site-packages/rest_framework/serializers.py", line 745, in data
    ret = super().data
          ^^^^^^^^^^^^
  File "/Users/mac/Desktop/work/game-server/venv/lib/python3.11/site-packages/rest_framework/serializers.py", line 246, in data
    self._data = self.to_representation(self.instance)
                 ^^^^^^^^^^^^^^^^^^^^^^^^^^^^^^^^^^^^^
  File "/Users/mac/Desktop/work/game-server/venv/lib/python3.11/site-packages/rest_framework/serializers.py", line 663, in to_representation
    return [
           ^
  File "/Users/mac/Desktop/work/game-server/venv/lib/python3.11/site-packages/rest_framework/serializers.py", line 664, in <listcomp>
    self.child.to_representation(item) for item in iterable
    ^^^^^^^^^^^^^^^^^^^^^^^^^^^^^^^^^^
  File "/Users/mac/Desktop/work/game-server/venv/lib/python3.11/site-packages/rest_framework/serializers.py", line 515, in to_representation
    ret[field.field_name] = field.to_representation(attribute)
                            ^^^^^^^^^^^^^^^^^^^^^^^^^^^^^^^^^^
  File "/Users/mac/Desktop/work/game-server/venv/lib/python3.11/site-packages/rest_framework/fields.py", line 963, in to_representation
    return int(value)
           ^^^^^^^^^^
ValueError: invalid literal for int() with base 10: 'AG电子'

[2023-12-29 12:04:22,788][apps.admin.utils.exceptions.op_exception_handler():78] [ERROR] Traceback (most recent call last):
  File "/Users/mac/Desktop/work/game-server/venv/lib/python3.11/site-packages/rest_framework/views.py", line 506, in dispatch
    response = handler(request, *args, **kwargs)
               ^^^^^^^^^^^^^^^^^^^^^^^^^^^^^^^^^
  File "/Users/mac/Desktop/work/game-server/apps/admin/op_drf/mixins.py", line 47, in list
    return self.get_paginated_response(serializer.data)
                                       ^^^^^^^^^^^^^^^
  File "/Users/mac/Desktop/work/game-server/venv/lib/python3.11/site-packages/rest_framework/serializers.py", line 745, in data
    ret = super().data
          ^^^^^^^^^^^^
  File "/Users/mac/Desktop/work/game-server/venv/lib/python3.11/site-packages/rest_framework/serializers.py", line 246, in data
    self._data = self.to_representation(self.instance)
                 ^^^^^^^^^^^^^^^^^^^^^^^^^^^^^^^^^^^^^
  File "/Users/mac/Desktop/work/game-server/venv/lib/python3.11/site-packages/rest_framework/serializers.py", line 663, in to_representation
    return [
           ^
  File "/Users/mac/Desktop/work/game-server/venv/lib/python3.11/site-packages/rest_framework/serializers.py", line 664, in <listcomp>
    self.child.to_representation(item) for item in iterable
    ^^^^^^^^^^^^^^^^^^^^^^^^^^^^^^^^^^
  File "/Users/mac/Desktop/work/game-server/venv/lib/python3.11/site-packages/rest_framework/serializers.py", line 515, in to_representation
    ret[field.field_name] = field.to_representation(attribute)
                            ^^^^^^^^^^^^^^^^^^^^^^^^^^^^^^^^^^
  File "/Users/mac/Desktop/work/game-server/venv/lib/python3.11/site-packages/rest_framework/fields.py", line 963, in to_representation
    return int(value)
           ^^^^^^^^^^
TypeError: int() argument must be a string, a bytes-like object or a real number, not 'GameCategory'

[2023-12-29 12:04:32,170][apps.admin.utils.exceptions.op_exception_handler():78] [ERROR] Traceback (most recent call last):
  File "/Users/mac/Desktop/work/game-server/venv/lib/python3.11/site-packages/rest_framework/views.py", line 506, in dispatch
    response = handler(request, *args, **kwargs)
               ^^^^^^^^^^^^^^^^^^^^^^^^^^^^^^^^^
  File "/Users/mac/Desktop/work/game-server/apps/admin/op_drf/mixins.py", line 47, in list
    return self.get_paginated_response(serializer.data)
                                       ^^^^^^^^^^^^^^^
  File "/Users/mac/Desktop/work/game-server/venv/lib/python3.11/site-packages/rest_framework/serializers.py", line 745, in data
    ret = super().data
          ^^^^^^^^^^^^
  File "/Users/mac/Desktop/work/game-server/venv/lib/python3.11/site-packages/rest_framework/serializers.py", line 246, in data
    self._data = self.to_representation(self.instance)
                 ^^^^^^^^^^^^^^^^^^^^^^^^^^^^^^^^^^^^^
  File "/Users/mac/Desktop/work/game-server/venv/lib/python3.11/site-packages/rest_framework/serializers.py", line 663, in to_representation
    return [
           ^
  File "/Users/mac/Desktop/work/game-server/venv/lib/python3.11/site-packages/rest_framework/serializers.py", line 664, in <listcomp>
    self.child.to_representation(item) for item in iterable
    ^^^^^^^^^^^^^^^^^^^^^^^^^^^^^^^^^^
  File "/Users/mac/Desktop/work/game-server/venv/lib/python3.11/site-packages/rest_framework/serializers.py", line 515, in to_representation
    ret[field.field_name] = field.to_representation(attribute)
                            ^^^^^^^^^^^^^^^^^^^^^^^^^^^^^^^^^^
  File "/Users/mac/Desktop/work/game-server/venv/lib/python3.11/site-packages/rest_framework/fields.py", line 963, in to_representation
    return int(value)
           ^^^^^^^^^^
TypeError: int() argument must be a string, a bytes-like object or a real number, not 'GameCategory'

[2023-12-29 12:57:36,063][apps.admin.utils.exceptions.op_exception_handler():78] [ERROR] Traceback (most recent call last):
  File "/Users/mac/Desktop/work/game-server/venv/lib/python3.11/site-packages/rest_framework/fields.py", line 457, in get_attribute
    return get_attribute(instance, self.source_attrs)
           ^^^^^^^^^^^^^^^^^^^^^^^^^^^^^^^^^^^^^^^^^^
  File "/Users/mac/Desktop/work/game-server/venv/lib/python3.11/site-packages/rest_framework/fields.py", line 97, in get_attribute
    instance = getattr(instance, attr)
               ^^^^^^^^^^^^^^^^^^^^^^^
AttributeError: 'GameManufacturer' object has no attribute 'category'

During handling of the above exception, another exception occurred:

Traceback (most recent call last):
  File "/Users/mac/Desktop/work/game-server/venv/lib/python3.11/site-packages/rest_framework/views.py", line 506, in dispatch
    response = handler(request, *args, **kwargs)
               ^^^^^^^^^^^^^^^^^^^^^^^^^^^^^^^^^
  File "/Users/mac/Desktop/work/game-server/apps/admin/op_drf/mixins.py", line 47, in list
    return self.get_paginated_response(serializer.data)
                                       ^^^^^^^^^^^^^^^
  File "/Users/mac/Desktop/work/game-server/venv/lib/python3.11/site-packages/rest_framework/serializers.py", line 745, in data
    ret = super().data
          ^^^^^^^^^^^^
  File "/Users/mac/Desktop/work/game-server/venv/lib/python3.11/site-packages/rest_framework/serializers.py", line 246, in data
    self._data = self.to_representation(self.instance)
                 ^^^^^^^^^^^^^^^^^^^^^^^^^^^^^^^^^^^^^
  File "/Users/mac/Desktop/work/game-server/venv/lib/python3.11/site-packages/rest_framework/serializers.py", line 663, in to_representation
    return [
           ^
  File "/Users/mac/Desktop/work/game-server/venv/lib/python3.11/site-packages/rest_framework/serializers.py", line 664, in <listcomp>
    self.child.to_representation(item) for item in iterable
    ^^^^^^^^^^^^^^^^^^^^^^^^^^^^^^^^^^
  File "/Users/mac/Desktop/work/game-server/venv/lib/python3.11/site-packages/rest_framework/serializers.py", line 502, in to_representation
    attribute = field.get_attribute(instance)
                ^^^^^^^^^^^^^^^^^^^^^^^^^^^^^
  File "/Users/mac/Desktop/work/game-server/venv/lib/python3.11/site-packages/rest_framework/fields.py", line 490, in get_attribute
    raise type(exc)(msg)
AttributeError: Got AttributeError when attempting to get a value for field `category` on serializer `GameManufacturerSerializer`.
The serializer field might be named incorrectly and not match any attribute or key on the `GameManufacturer` instance.
Original exception text was: 'GameManufacturer' object has no attribute 'category'.

[2023-12-29 12:57:47,236][apps.admin.utils.exceptions.op_exception_handler():78] [ERROR] Traceback (most recent call last):
  File "/Users/mac/Desktop/work/game-server/venv/lib/python3.11/site-packages/rest_framework/fields.py", line 457, in get_attribute
    return get_attribute(instance, self.source_attrs)
           ^^^^^^^^^^^^^^^^^^^^^^^^^^^^^^^^^^^^^^^^^^
  File "/Users/mac/Desktop/work/game-server/venv/lib/python3.11/site-packages/rest_framework/fields.py", line 97, in get_attribute
    instance = getattr(instance, attr)
               ^^^^^^^^^^^^^^^^^^^^^^^
AttributeError: 'GameManufacturer' object has no attribute 'category'

During handling of the above exception, another exception occurred:

Traceback (most recent call last):
  File "/Users/mac/Desktop/work/game-server/venv/lib/python3.11/site-packages/rest_framework/views.py", line 506, in dispatch
    response = handler(request, *args, **kwargs)
               ^^^^^^^^^^^^^^^^^^^^^^^^^^^^^^^^^
  File "/Users/mac/Desktop/work/game-server/apps/admin/op_drf/mixins.py", line 47, in list
    return self.get_paginated_response(serializer.data)
                                       ^^^^^^^^^^^^^^^
  File "/Users/mac/Desktop/work/game-server/venv/lib/python3.11/site-packages/rest_framework/serializers.py", line 745, in data
    ret = super().data
          ^^^^^^^^^^^^
  File "/Users/mac/Desktop/work/game-server/venv/lib/python3.11/site-packages/rest_framework/serializers.py", line 246, in data
    self._data = self.to_representation(self.instance)
                 ^^^^^^^^^^^^^^^^^^^^^^^^^^^^^^^^^^^^^
  File "/Users/mac/Desktop/work/game-server/venv/lib/python3.11/site-packages/rest_framework/serializers.py", line 663, in to_representation
    return [
           ^
  File "/Users/mac/Desktop/work/game-server/venv/lib/python3.11/site-packages/rest_framework/serializers.py", line 664, in <listcomp>
    self.child.to_representation(item) for item in iterable
    ^^^^^^^^^^^^^^^^^^^^^^^^^^^^^^^^^^
  File "/Users/mac/Desktop/work/game-server/venv/lib/python3.11/site-packages/rest_framework/serializers.py", line 502, in to_representation
    attribute = field.get_attribute(instance)
                ^^^^^^^^^^^^^^^^^^^^^^^^^^^^^
  File "/Users/mac/Desktop/work/game-server/venv/lib/python3.11/site-packages/rest_framework/fields.py", line 490, in get_attribute
    raise type(exc)(msg)
AttributeError: Got AttributeError when attempting to get a value for field `category` on serializer `GameManufacturerSerializer`.
The serializer field might be named incorrectly and not match any attribute or key on the `GameManufacturer` instance.
Original exception text was: 'GameManufacturer' object has no attribute 'category'.

[2023-12-29 12:58:41,004][apps.admin.utils.exceptions.op_exception_handler():78] [ERROR] Traceback (most recent call last):
  File "/Users/mac/Desktop/work/game-server/venv/lib/python3.11/site-packages/rest_framework/views.py", line 506, in dispatch
    response = handler(request, *args, **kwargs)
               ^^^^^^^^^^^^^^^^^^^^^^^^^^^^^^^^^
  File "/Users/mac/Desktop/work/game-server/apps/admin/op_drf/mixins.py", line 47, in list
    return self.get_paginated_response(serializer.data)
                                       ^^^^^^^^^^^^^^^
  File "/Users/mac/Desktop/work/game-server/venv/lib/python3.11/site-packages/rest_framework/serializers.py", line 745, in data
    ret = super().data
          ^^^^^^^^^^^^
  File "/Users/mac/Desktop/work/game-server/venv/lib/python3.11/site-packages/rest_framework/serializers.py", line 246, in data
    self._data = self.to_representation(self.instance)
                 ^^^^^^^^^^^^^^^^^^^^^^^^^^^^^^^^^^^^^
  File "/Users/mac/Desktop/work/game-server/venv/lib/python3.11/site-packages/rest_framework/serializers.py", line 663, in to_representation
    return [
           ^
  File "/Users/mac/Desktop/work/game-server/venv/lib/python3.11/site-packages/rest_framework/serializers.py", line 664, in <listcomp>
    self.child.to_representation(item) for item in iterable
    ^^^^^^^^^^^^^^^^^^^^^^^^^^^^^^^^^^
  File "/Users/mac/Desktop/work/game-server/venv/lib/python3.11/site-packages/rest_framework/serializers.py", line 500, in to_representation
    for field in fields:
  File "/Users/mac/Desktop/work/game-server/venv/lib/python3.11/site-packages/rest_framework/serializers.py", line 361, in _readable_fields
    for field in self.fields.values():
                 ^^^^^^^^^^^
  File "/Users/mac/Desktop/work/game-server/venv/lib/python3.11/site-packages/django/utils/functional.py", line 80, in __get__
    res = instance.__dict__[self.name] = self.func(instance)
                                         ^^^^^^^^^^^^^^^^^^^
  File "/Users/mac/Desktop/work/game-server/apps/admin/op_drf/serializers.py", line 63, in fields
    for key, value in self.get_fields().items():
                      ^^^^^^^^^^^^^^^^^
  File "/Users/mac/Desktop/work/game-server/venv/lib/python3.11/site-packages/rest_framework/serializers.py", line 1029, in get_fields
    field_names = self.get_field_names(declared_fields, info)
                  ^^^^^^^^^^^^^^^^^^^^^^^^^^^^^^^^^^^^^^^^^^^
  File "/Users/mac/Desktop/work/game-server/venv/lib/python3.11/site-packages/rest_framework/serializers.py", line 1125, in get_field_names
    assert field_name in fields, (
           ^^^^^^^^^^^^^^^^^^^^
AssertionError: The field 'gameCategory' was declared on serializer GameManufacturerSerializer, but has not been included in the 'fields' option.

[2023-12-29 12:58:58,950][apps.admin.utils.exceptions.op_exception_handler():78] [ERROR] Traceback (most recent call last):
  File "/Users/mac/Desktop/work/game-server/venv/lib/python3.11/site-packages/rest_framework/views.py", line 506, in dispatch
    response = handler(request, *args, **kwargs)
               ^^^^^^^^^^^^^^^^^^^^^^^^^^^^^^^^^
  File "/Users/mac/Desktop/work/game-server/apps/admin/op_drf/mixins.py", line 47, in list
    return self.get_paginated_response(serializer.data)
                                       ^^^^^^^^^^^^^^^
  File "/Users/mac/Desktop/work/game-server/venv/lib/python3.11/site-packages/rest_framework/serializers.py", line 745, in data
    ret = super().data
          ^^^^^^^^^^^^
  File "/Users/mac/Desktop/work/game-server/venv/lib/python3.11/site-packages/rest_framework/serializers.py", line 246, in data
    self._data = self.to_representation(self.instance)
                 ^^^^^^^^^^^^^^^^^^^^^^^^^^^^^^^^^^^^^
  File "/Users/mac/Desktop/work/game-server/venv/lib/python3.11/site-packages/rest_framework/serializers.py", line 663, in to_representation
    return [
           ^
  File "/Users/mac/Desktop/work/game-server/venv/lib/python3.11/site-packages/rest_framework/serializers.py", line 664, in <listcomp>
    self.child.to_representation(item) for item in iterable
    ^^^^^^^^^^^^^^^^^^^^^^^^^^^^^^^^^^
  File "/Users/mac/Desktop/work/game-server/venv/lib/python3.11/site-packages/rest_framework/serializers.py", line 500, in to_representation
    for field in fields:
  File "/Users/mac/Desktop/work/game-server/venv/lib/python3.11/site-packages/rest_framework/serializers.py", line 361, in _readable_fields
    for field in self.fields.values():
                 ^^^^^^^^^^^
  File "/Users/mac/Desktop/work/game-server/venv/lib/python3.11/site-packages/django/utils/functional.py", line 80, in __get__
    res = instance.__dict__[self.name] = self.func(instance)
                                         ^^^^^^^^^^^^^^^^^^^
  File "/Users/mac/Desktop/work/game-server/apps/admin/op_drf/serializers.py", line 63, in fields
    for key, value in self.get_fields().items():
                      ^^^^^^^^^^^^^^^^^
  File "/Users/mac/Desktop/work/game-server/venv/lib/python3.11/site-packages/rest_framework/serializers.py", line 1029, in get_fields
    field_names = self.get_field_names(declared_fields, info)
                  ^^^^^^^^^^^^^^^^^^^^^^^^^^^^^^^^^^^^^^^^^^^
  File "/Users/mac/Desktop/work/game-server/venv/lib/python3.11/site-packages/rest_framework/serializers.py", line 1125, in get_field_names
    assert field_name in fields, (
           ^^^^^^^^^^^^^^^^^^^^
AssertionError: The field 'gameCategory' was declared on serializer GameManufacturerSerializer, but has not been included in the 'fields' option.

[2023-12-29 20:00:11,344][apps.admin.utils.exceptions.op_exception_handler():78] [ERROR] Traceback (most recent call last):
  File "/Users/mac/Desktop/work/game-server/venv/lib/python3.11/site-packages/rest_framework/views.py", line 506, in dispatch
    response = handler(request, *args, **kwargs)
               ^^^^^^^^^^^^^^^^^^^^^^^^^^^^^^^^^
  File "/Users/mac/Desktop/work/game-server/apps/admin/op_drf/mixins.py", line 47, in list
    return self.get_paginated_response(serializer.data)
                                       ^^^^^^^^^^^^^^^
  File "/Users/mac/Desktop/work/game-server/venv/lib/python3.11/site-packages/rest_framework/serializers.py", line 745, in data
    ret = super().data
          ^^^^^^^^^^^^
  File "/Users/mac/Desktop/work/game-server/venv/lib/python3.11/site-packages/rest_framework/serializers.py", line 246, in data
    self._data = self.to_representation(self.instance)
                 ^^^^^^^^^^^^^^^^^^^^^^^^^^^^^^^^^^^^^
  File "/Users/mac/Desktop/work/game-server/venv/lib/python3.11/site-packages/rest_framework/serializers.py", line 663, in to_representation
    return [
           ^
  File "/Users/mac/Desktop/work/game-server/venv/lib/python3.11/site-packages/rest_framework/serializers.py", line 664, in <listcomp>
    self.child.to_representation(item) for item in iterable
    ^^^^^^^^^^^^^^^^^^^^^^^^^^^^^^^^^^
  File "/Users/mac/Desktop/work/game-server/venv/lib/python3.11/site-packages/rest_framework/serializers.py", line 500, in to_representation
    for field in fields:
  File "/Users/mac/Desktop/work/game-server/venv/lib/python3.11/site-packages/rest_framework/serializers.py", line 361, in _readable_fields
    for field in self.fields.values():
                 ^^^^^^^^^^^
  File "/Users/mac/Desktop/work/game-server/venv/lib/python3.11/site-packages/django/utils/functional.py", line 80, in __get__
    res = instance.__dict__[self.name] = self.func(instance)
                                         ^^^^^^^^^^^^^^^^^^^
  File "/Users/mac/Desktop/work/game-server/apps/admin/op_drf/serializers.py", line 63, in fields
    for key, value in self.get_fields().items():
                      ^^^^^^^^^^^^^^^^^
  File "/Users/mac/Desktop/work/game-server/venv/lib/python3.11/site-packages/rest_framework/serializers.py", line 1029, in get_fields
    field_names = self.get_field_names(declared_fields, info)
                  ^^^^^^^^^^^^^^^^^^^^^^^^^^^^^^^^^^^^^^^^^^^
  File "/Users/mac/Desktop/work/game-server/venv/lib/python3.11/site-packages/rest_framework/serializers.py", line 1125, in get_field_names
    assert field_name in fields, (
           ^^^^^^^^^^^^^^^^^^^^
AssertionError: The field 'gameCategory' was declared on serializer GameManufacturerSerializer, but has not been included in the 'fields' option.

[2024-01-02 20:34:21,727][django.request.log_response():222] [ERROR] Internal Server Error: /api/app/register
Traceback (most recent call last):
  File "/Users/mac/Desktop/work/game-server/venv/lib/python3.11/site-packages/django/core/handlers/exception.py", line 34, in inner
    response = get_response(request)
               ^^^^^^^^^^^^^^^^^^^^^
  File "/Users/mac/Desktop/work/game-server/venv/lib/python3.11/site-packages/django/utils/deprecation.py", line 93, in __call__
    response = self.process_request(request)
               ^^^^^^^^^^^^^^^^^^^^^^^^^^^^^
  File "/Users/mac/Desktop/work/game-server/venv/lib/python3.11/site-packages/django/middleware/common.py", line 53, in process_request
    path = self.get_full_path_with_slash(request)
           ^^^^^^^^^^^^^^^^^^^^^^^^^^^^^^^^^^^^^^
  File "/Users/mac/Desktop/work/game-server/venv/lib/python3.11/site-packages/django/middleware/common.py", line 86, in get_full_path_with_slash
    raise RuntimeError(
RuntimeError: You called this URL via POST, but the URL doesn't end in a slash and you have APPEND_SLASH set. Django can't redirect to the slash URL while maintaining POST data. Change your form to point to 127.0.0.1:8000/api/app/register/ (note the trailing slash), or set APPEND_SLASH=False in your Django settings.
[2024-01-04 10:05:44,610][apps.admin.utils.exceptions.op_exception_handler():78] [ERROR] Traceback (most recent call last):
  File "/Users/mac/Desktop/work/game-server/venv/lib/python3.11/site-packages/rest_framework/views.py", line 497, in dispatch
    self.initial(request, *args, **kwargs)
  File "/Users/mac/Desktop/work/game-server/venv/lib/python3.11/site-packages/rest_framework/views.py", line 406, in initial
    neg = self.perform_content_negotiation(request)
          ^^^^^^^^^^^^^^^^^^^^^^^^^^^^^^^^^^^^^^^^^
  File "/Users/mac/Desktop/work/game-server/venv/lib/python3.11/site-packages/rest_framework/views.py", line 310, in perform_content_negotiation
    return conneg.select_renderer(request, renderers, self.format_kwarg)
           ^^^^^^^^^^^^^^^^^^^^^^^^^^^^^^^^^^^^^^^^^^^^^^^^^^^^^^^^^^^^^
  File "/Users/mac/Desktop/work/game-server/venv/lib/python3.11/site-packages/rest_framework/negotiation.py", line 45, in select_renderer
    renderers = self.filter_renderers(renderers, format)
                ^^^^^^^^^^^^^^^^^^^^^^^^^^^^^^^^^^^^^^^^
  File "/Users/mac/Desktop/work/game-server/venv/lib/python3.11/site-packages/rest_framework/negotiation.py", line 86, in filter_renderers
    raise Http404
django.http.response.Http404

[2024-01-04 10:28:01,851][apps.admin.utils.exceptions.op_exception_handler():78] [ERROR] Traceback (most recent call last):
  File "/Users/mac/Desktop/work/game-server/venv/lib/python3.11/site-packages/rest_framework/views.py", line 506, in dispatch
    response = handler(request, *args, **kwargs)
               ^^^^^^^^^^^^^^^^^^^^^^^^^^^^^^^^^
  File "/Users/mac/Desktop/work/game-server/venv/lib/python3.11/site-packages/drf_yasg/views.py", line 94, in get
    schema = generator.get_schema(request, self.public)
             ^^^^^^^^^^^^^^^^^^^^^^^^^^^^^^^^^^^^^^^^^^
  File "/Users/mac/Desktop/work/game-server/venv/lib/python3.11/site-packages/drf_yasg/generators.py", line 246, in get_schema
    paths, prefix = self.get_paths(endpoints, components, request, public)
                    ^^^^^^^^^^^^^^^^^^^^^^^^^^^^^^^^^^^^^^^^^^^^^^^^^^^^^^
  File "/Users/mac/Desktop/work/game-server/venv/lib/python3.11/site-packages/drf_yasg/generators.py", line 404, in get_paths
    operation = self.get_operation(view, path, prefix, method, components, request)
                ^^^^^^^^^^^^^^^^^^^^^^^^^^^^^^^^^^^^^^^^^^^^^^^^^^^^^^^^^^^^^^^^^^^
  File "/Users/mac/Desktop/work/game-server/venv/lib/python3.11/site-packages/drf_yasg/generators.py", line 446, in get_operation
    operation = view_inspector.get_operation(operation_keys)
                ^^^^^^^^^^^^^^^^^^^^^^^^^^^^^^^^^^^^^^^^^^^^
  File "/Users/mac/Desktop/work/game-server/venv/lib/python3.11/site-packages/drf_yasg/inspectors/view.py", line 45, in get_operation
    responses = self.get_responses()
                ^^^^^^^^^^^^^^^^^^^^
  File "/Users/mac/Desktop/work/game-server/venv/lib/python3.11/site-packages/drf_yasg/inspectors/view.py", line 180, in get_responses
    response_serializers = self.get_response_serializers()
                           ^^^^^^^^^^^^^^^^^^^^^^^^^^^^^^^
  File "/Users/mac/Desktop/work/game-server/venv/lib/python3.11/site-packages/drf_yasg/inspectors/view.py", line 235, in get_response_serializers
    responses = self.get_default_responses()
                ^^^^^^^^^^^^^^^^^^^^^^^^^^^^
  File "/Users/mac/Desktop/work/game-server/venv/lib/python3.11/site-packages/drf_yasg/inspectors/view.py", line 211, in get_default_responses
    default_schema = self.serializer_to_schema(default_schema) or ''
                     ^^^^^^^^^^^^^^^^^^^^^^^^^^^^^^^^^^^^^^^^^
  File "/Users/mac/Desktop/work/game-server/venv/lib/python3.11/site-packages/drf_yasg/inspectors/base.py", line 437, in serializer_to_schema
    return self.probe_inspectors(
           ^^^^^^^^^^^^^^^^^^^^^^
  File "/Users/mac/Desktop/work/game-server/venv/lib/python3.11/site-packages/drf_yasg/inspectors/base.py", line 110, in probe_inspectors
    result = method(obj, **kwargs)
             ^^^^^^^^^^^^^^^^^^^^^
  File "/Users/mac/Desktop/work/game-server/venv/lib/python3.11/site-packages/drf_yasg/inspectors/field.py", line 33, in get_schema
    return self.probe_field_inspectors(serializer, openapi.Schema, self.use_definitions)
           ^^^^^^^^^^^^^^^^^^^^^^^^^^^^^^^^^^^^^^^^^^^^^^^^^^^^^^^^^^^^^^^^^^^^^^^^^^^^^
  File "/Users/mac/Desktop/work/game-server/venv/lib/python3.11/site-packages/drf_yasg/inspectors/base.py", line 228, in probe_field_inspectors
    return self.probe_inspectors(
           ^^^^^^^^^^^^^^^^^^^^^^
  File "/Users/mac/Desktop/work/game-server/venv/lib/python3.11/site-packages/drf_yasg/inspectors/base.py", line 110, in probe_inspectors
    result = method(obj, **kwargs)
             ^^^^^^^^^^^^^^^^^^^^^
  File "/Users/mac/Desktop/work/game-server/venv/lib/python3.11/site-packages/drf_yasg/inspectors/field.py", line 132, in field_to_swagger_object
    raise SwaggerGenerationError(
drf_yasg.errors.SwaggerGenerationError: Schema for <class 'apps.admin.member.serializers.UserProfileSerializer'> would override distinct serializer <class 'apps.admin.permission.serializers.UserProfileSerializer'> because they implicitly share the same ref_name; explicitly set the ref_name attribute on both serializers' Meta classes

[2024-01-04 16:05:39,402][django.request.log_response():222] [ERROR] Internal Server Error: /admin/games/gameCategory/update
Traceback (most recent call last):
  File "/Users/mac/Desktop/work/game-server/venv/lib/python3.11/site-packages/django/core/handlers/exception.py", line 34, in inner
    response = get_response(request)
               ^^^^^^^^^^^^^^^^^^^^^
  File "/Users/mac/Desktop/work/game-server/venv/lib/python3.11/site-packages/django/utils/deprecation.py", line 93, in __call__
    response = self.process_request(request)
               ^^^^^^^^^^^^^^^^^^^^^^^^^^^^^
  File "/Users/mac/Desktop/work/game-server/venv/lib/python3.11/site-packages/django/middleware/common.py", line 53, in process_request
    path = self.get_full_path_with_slash(request)
           ^^^^^^^^^^^^^^^^^^^^^^^^^^^^^^^^^^^^^^
  File "/Users/mac/Desktop/work/game-server/venv/lib/python3.11/site-packages/django/middleware/common.py", line 86, in get_full_path_with_slash
    raise RuntimeError(
RuntimeError: You called this URL via POST, but the URL doesn't end in a slash and you have APPEND_SLASH set. Django can't redirect to the slash URL while maintaining POST data. Change your form to point to 127.0.0.1:8000/admin/games/gameCategory/update/ (note the trailing slash), or set APPEND_SLASH=False in your Django settings.
[2024-01-04 16:05:59,382][django.request.log_response():222] [ERROR] Internal Server Error: /admin/games/gameCategory/update
Traceback (most recent call last):
  File "/Users/mac/Desktop/work/game-server/venv/lib/python3.11/site-packages/django/core/handlers/exception.py", line 34, in inner
    response = get_response(request)
               ^^^^^^^^^^^^^^^^^^^^^
  File "/Users/mac/Desktop/work/game-server/venv/lib/python3.11/site-packages/django/utils/deprecation.py", line 93, in __call__
    response = self.process_request(request)
               ^^^^^^^^^^^^^^^^^^^^^^^^^^^^^
  File "/Users/mac/Desktop/work/game-server/venv/lib/python3.11/site-packages/django/middleware/common.py", line 53, in process_request
    path = self.get_full_path_with_slash(request)
           ^^^^^^^^^^^^^^^^^^^^^^^^^^^^^^^^^^^^^^
  File "/Users/mac/Desktop/work/game-server/venv/lib/python3.11/site-packages/django/middleware/common.py", line 86, in get_full_path_with_slash
    raise RuntimeError(
RuntimeError: You called this URL via POST, but the URL doesn't end in a slash and you have APPEND_SLASH set. Django can't redirect to the slash URL while maintaining POST data. Change your form to point to 127.0.0.1:8000/admin/games/gameCategory/update/ (note the trailing slash), or set APPEND_SLASH=False in your Django settings.
[2024-01-04 16:51:51,746][apps.admin.utils.exceptions.op_exception_handler():78] [ERROR] Traceback (most recent call last):
  File "/Users/mac/Desktop/work/game-server/venv/lib/python3.11/site-packages/rest_framework/serializers.py", line 939, in create
    instance = ModelClass._default_manager.create(**validated_data)
               ^^^^^^^^^^^^^^^^^^^^^^^^^^^^^^^^^^^^^^^^^^^^^^^^^^^^
  File "/Users/mac/Desktop/work/game-server/venv/lib/python3.11/site-packages/django/db/models/manager.py", line 82, in manager_method
    return getattr(self.get_queryset(), name)(*args, **kwargs)
           ^^^^^^^^^^^^^^^^^^^^^^^^^^^^^^^^^^^^^^^^^^^^^^^^^^^
  File "/Users/mac/Desktop/work/game-server/venv/lib/python3.11/site-packages/django/db/models/query.py", line 420, in create
    obj = self.model(**kwargs)
          ^^^^^^^^^^^^^^^^^^^^
  File "/Users/mac/Desktop/work/game-server/venv/lib/python3.11/site-packages/django/db/models/base.py", line 501, in __init__
    raise TypeError("%s() got an unexpected keyword argument '%s'" % (cls.__name__, kwarg))
TypeError: Games() got an unexpected keyword argument 'gameCategory_id'

During handling of the above exception, another exception occurred:

Traceback (most recent call last):
  File "/Users/mac/Desktop/work/game-server/venv/lib/python3.11/site-packages/rest_framework/views.py", line 506, in dispatch
    response = handler(request, *args, **kwargs)
               ^^^^^^^^^^^^^^^^^^^^^^^^^^^^^^^^^
  File "/usr/local/Cellar/python@3.11/3.11.3/Frameworks/Python.framework/Versions/3.11/lib/python3.11/contextlib.py", line 81, in inner
    return func(*args, **kwds)
           ^^^^^^^^^^^^^^^^^^^
  File "/Users/mac/Desktop/work/game-server/apps/admin/game/views.py", line 163, in add_games
    serializer.save()
  File "/Users/mac/Desktop/work/game-server/apps/admin/op_drf/serializers.py", line 34, in save
    return super().save(**kwargs)
           ^^^^^^^^^^^^^^^^^^^^^^
  File "/Users/mac/Desktop/work/game-server/venv/lib/python3.11/site-packages/rest_framework/serializers.py", line 205, in save
    self.instance = self.create(validated_data)
                    ^^^^^^^^^^^^^^^^^^^^^^^^^^^
  File "/Users/mac/Desktop/work/game-server/apps/admin/op_drf/serializers.py", line 47, in create
    return super().create(validated_data)
           ^^^^^^^^^^^^^^^^^^^^^^^^^^^^^^
  File "/Users/mac/Desktop/work/game-server/venv/lib/python3.11/site-packages/rest_framework/serializers.py", line 958, in create
    raise TypeError(msg)
TypeError: Got a `TypeError` when calling `Games.objects.create()`. This may be because you have a writable field on the serializer class that is not a valid argument to `Games.objects.create()`. You may need to make the field read-only, or override the GamesSerializer.create() method to handle this correctly.
Original exception was:
 Traceback (most recent call last):
  File "/Users/mac/Desktop/work/game-server/venv/lib/python3.11/site-packages/rest_framework/serializers.py", line 939, in create
    instance = ModelClass._default_manager.create(**validated_data)
               ^^^^^^^^^^^^^^^^^^^^^^^^^^^^^^^^^^^^^^^^^^^^^^^^^^^^
  File "/Users/mac/Desktop/work/game-server/venv/lib/python3.11/site-packages/django/db/models/manager.py", line 82, in manager_method
    return getattr(self.get_queryset(), name)(*args, **kwargs)
           ^^^^^^^^^^^^^^^^^^^^^^^^^^^^^^^^^^^^^^^^^^^^^^^^^^^
  File "/Users/mac/Desktop/work/game-server/venv/lib/python3.11/site-packages/django/db/models/query.py", line 420, in create
    obj = self.model(**kwargs)
          ^^^^^^^^^^^^^^^^^^^^
  File "/Users/mac/Desktop/work/game-server/venv/lib/python3.11/site-packages/django/db/models/base.py", line 501, in __init__
    raise TypeError("%s() got an unexpected keyword argument '%s'" % (cls.__name__, kwarg))
TypeError: Games() got an unexpected keyword argument 'gameCategory_id'


[2024-01-04 16:52:20,520][apps.admin.utils.exceptions.op_exception_handler():78] [ERROR] Traceback (most recent call last):
  File "/Users/mac/Desktop/work/game-server/venv/lib/python3.11/site-packages/rest_framework/serializers.py", line 939, in create
    instance = ModelClass._default_manager.create(**validated_data)
               ^^^^^^^^^^^^^^^^^^^^^^^^^^^^^^^^^^^^^^^^^^^^^^^^^^^^
  File "/Users/mac/Desktop/work/game-server/venv/lib/python3.11/site-packages/django/db/models/manager.py", line 82, in manager_method
    return getattr(self.get_queryset(), name)(*args, **kwargs)
           ^^^^^^^^^^^^^^^^^^^^^^^^^^^^^^^^^^^^^^^^^^^^^^^^^^^
  File "/Users/mac/Desktop/work/game-server/venv/lib/python3.11/site-packages/django/db/models/query.py", line 420, in create
    obj = self.model(**kwargs)
          ^^^^^^^^^^^^^^^^^^^^
  File "/Users/mac/Desktop/work/game-server/venv/lib/python3.11/site-packages/django/db/models/base.py", line 501, in __init__
    raise TypeError("%s() got an unexpected keyword argument '%s'" % (cls.__name__, kwarg))
TypeError: Games() got an unexpected keyword argument 'gameCategory_id'

During handling of the above exception, another exception occurred:

Traceback (most recent call last):
  File "/Users/mac/Desktop/work/game-server/venv/lib/python3.11/site-packages/rest_framework/views.py", line 506, in dispatch
    response = handler(request, *args, **kwargs)
               ^^^^^^^^^^^^^^^^^^^^^^^^^^^^^^^^^
  File "/usr/local/Cellar/python@3.11/3.11.3/Frameworks/Python.framework/Versions/3.11/lib/python3.11/contextlib.py", line 81, in inner
    return func(*args, **kwds)
           ^^^^^^^^^^^^^^^^^^^
  File "/Users/mac/Desktop/work/game-server/apps/admin/game/views.py", line 163, in add_games
    serializer.save()
  File "/Users/mac/Desktop/work/game-server/apps/admin/op_drf/serializers.py", line 34, in save
    return super().save(**kwargs)
           ^^^^^^^^^^^^^^^^^^^^^^
  File "/Users/mac/Desktop/work/game-server/venv/lib/python3.11/site-packages/rest_framework/serializers.py", line 205, in save
    self.instance = self.create(validated_data)
                    ^^^^^^^^^^^^^^^^^^^^^^^^^^^
  File "/Users/mac/Desktop/work/game-server/apps/admin/op_drf/serializers.py", line 47, in create
    return super().create(validated_data)
           ^^^^^^^^^^^^^^^^^^^^^^^^^^^^^^
  File "/Users/mac/Desktop/work/game-server/venv/lib/python3.11/site-packages/rest_framework/serializers.py", line 958, in create
    raise TypeError(msg)
TypeError: Got a `TypeError` when calling `Games.objects.create()`. This may be because you have a writable field on the serializer class that is not a valid argument to `Games.objects.create()`. You may need to make the field read-only, or override the GamesSerializer.create() method to handle this correctly.
Original exception was:
 Traceback (most recent call last):
  File "/Users/mac/Desktop/work/game-server/venv/lib/python3.11/site-packages/rest_framework/serializers.py", line 939, in create
    instance = ModelClass._default_manager.create(**validated_data)
               ^^^^^^^^^^^^^^^^^^^^^^^^^^^^^^^^^^^^^^^^^^^^^^^^^^^^
  File "/Users/mac/Desktop/work/game-server/venv/lib/python3.11/site-packages/django/db/models/manager.py", line 82, in manager_method
    return getattr(self.get_queryset(), name)(*args, **kwargs)
           ^^^^^^^^^^^^^^^^^^^^^^^^^^^^^^^^^^^^^^^^^^^^^^^^^^^
  File "/Users/mac/Desktop/work/game-server/venv/lib/python3.11/site-packages/django/db/models/query.py", line 420, in create
    obj = self.model(**kwargs)
          ^^^^^^^^^^^^^^^^^^^^
  File "/Users/mac/Desktop/work/game-server/venv/lib/python3.11/site-packages/django/db/models/base.py", line 501, in __init__
    raise TypeError("%s() got an unexpected keyword argument '%s'" % (cls.__name__, kwarg))
TypeError: Games() got an unexpected keyword argument 'gameCategory_id'


[2024-01-04 16:52:57,444][apps.admin.utils.exceptions.op_exception_handler():78] [ERROR] Traceback (most recent call last):
  File "/Users/mac/Desktop/work/game-server/venv/lib/python3.11/site-packages/rest_framework/views.py", line 506, in dispatch
    response = handler(request, *args, **kwargs)
               ^^^^^^^^^^^^^^^^^^^^^^^^^^^^^^^^^
  File "/usr/local/Cellar/python@3.11/3.11.3/Frameworks/Python.framework/Versions/3.11/lib/python3.11/contextlib.py", line 81, in inner
    return func(*args, **kwds)
           ^^^^^^^^^^^^^^^^^^^
  File "/Users/mac/Desktop/work/game-server/apps/admin/game/views.py", line 157, in add_games
    gamesObj = self.queryset.filter(gameCategory_id=jsonData.get('gameCategory')).filter(
               ^^^^^^^^^^^^^^^^^^^^^^^^^^^^^^^^^^^^^^^^^^^^^^^^^^^^^^^^^^^^^^^^^^
  File "/Users/mac/Desktop/work/game-server/venv/lib/python3.11/site-packages/django/db/models/query.py", line 892, in filter
    return self._filter_or_exclude(False, *args, **kwargs)
           ^^^^^^^^^^^^^^^^^^^^^^^^^^^^^^^^^^^^^^^^^^^^^^^
  File "/Users/mac/Desktop/work/game-server/venv/lib/python3.11/site-packages/django/db/models/query.py", line 910, in _filter_or_exclude
    clone.query.add_q(Q(*args, **kwargs))
  File "/Users/mac/Desktop/work/game-server/venv/lib/python3.11/site-packages/django/db/models/sql/query.py", line 1290, in add_q
    clause, _ = self._add_q(q_object, self.used_aliases)
                ^^^^^^^^^^^^^^^^^^^^^^^^^^^^^^^^^^^^^^^^
  File "/Users/mac/Desktop/work/game-server/venv/lib/python3.11/site-packages/django/db/models/sql/query.py", line 1315, in _add_q
    child_clause, needed_inner = self.build_filter(
                                 ^^^^^^^^^^^^^^^^^^
  File "/Users/mac/Desktop/work/game-server/venv/lib/python3.11/site-packages/django/db/models/sql/query.py", line 1190, in build_filter
    lookups, parts, reffed_expression = self.solve_lookup_type(arg)
                                        ^^^^^^^^^^^^^^^^^^^^^^^^^^^
  File "/Users/mac/Desktop/work/game-server/venv/lib/python3.11/site-packages/django/db/models/sql/query.py", line 1049, in solve_lookup_type
    _, field, _, lookup_parts = self.names_to_path(lookup_splitted, self.get_meta())
                                ^^^^^^^^^^^^^^^^^^^^^^^^^^^^^^^^^^^^^^^^^^^^^^^^^^^^
  File "/Users/mac/Desktop/work/game-server/venv/lib/python3.11/site-packages/django/db/models/sql/query.py", line 1419, in names_to_path
    raise FieldError("Cannot resolve keyword '%s' into field. "
django.core.exceptions.FieldError: Cannot resolve keyword 'gameCategory_id' into field. Choices are: create_datetime, creator, creator_id, dept_belong_id, description, gameManufacturer, gameManufacturer_id, id, isDel, isHot, isRecommend, modifier, name, sort, status, update_datetime, uri, url

[2024-01-09 18:30:32,602][apps.admin.utils.exceptions.op_exception_handler():78] [ERROR] Traceback (most recent call last):
  File "/Users/mac/Desktop/work/game-server/venv/lib/python3.11/site-packages/rest_framework/views.py", line 506, in dispatch
    response = handler(request, *args, **kwargs)
               ^^^^^^^^^^^^^^^^^^^^^^^^^^^^^^^^^
  File "/Users/mac/Desktop/work/game-server/apps/admin/op_drf/mixins.py", line 22, in create
    self.perform_create(serializer)
  File "/Users/mac/Desktop/work/game-server/apps/admin/op_drf/mixins.py", line 29, in perform_create
    super().perform_create(serializer)
  File "/Users/mac/Desktop/work/game-server/venv/lib/python3.11/site-packages/rest_framework/mixins.py", line 24, in perform_create
    serializer.save()
  File "/Users/mac/Desktop/work/game-server/apps/admin/permission/serializers.py", line 284, in save
    data.role.set(self.initial_data.get('roleIds'))
  File "/Users/mac/Desktop/work/game-server/venv/lib/python3.11/site-packages/django/db/models/fields/related_descriptors.py", line 975, in set
    objs = tuple(objs)
           ^^^^^^^^^^^
TypeError: 'int' object is not iterable

[2024-01-09 18:30:56,215][apps.admin.utils.exceptions.op_exception_handler():78] [ERROR] Traceback (most recent call last):
  File "/Users/mac/Desktop/work/game-server/venv/lib/python3.11/site-packages/rest_framework/views.py", line 506, in dispatch
    response = handler(request, *args, **kwargs)
               ^^^^^^^^^^^^^^^^^^^^^^^^^^^^^^^^^
  File "/Users/mac/Desktop/work/game-server/apps/admin/op_drf/mixins.py", line 21, in create
    serializer.is_valid(raise_exception=True)
  File "/Users/mac/Desktop/work/game-server/venv/lib/python3.11/site-packages/rest_framework/serializers.py", line 220, in is_valid
    self._validated_data = self.run_validation(self.initial_data)
                           ^^^^^^^^^^^^^^^^^^^^^^^^^^^^^^^^^^^^^^
  File "/Users/mac/Desktop/work/game-server/venv/lib/python3.11/site-packages/rest_framework/serializers.py", line 419, in run_validation
    value = self.to_internal_value(data)
            ^^^^^^^^^^^^^^^^^^^^^^^^^^^^
  File "/Users/mac/Desktop/work/game-server/venv/lib/python3.11/site-packages/rest_framework/serializers.py", line 476, in to_internal_value
    validated_value = field.run_validation(primitive_value)
                      ^^^^^^^^^^^^^^^^^^^^^^^^^^^^^^^^^^^^^
  File "/Users/mac/Desktop/work/game-server/venv/lib/python3.11/site-packages/rest_framework/fields.py", line 799, in run_validation
    return super().run_validation(data)
           ^^^^^^^^^^^^^^^^^^^^^^^^^^^^
  File "/Users/mac/Desktop/work/game-server/venv/lib/python3.11/site-packages/rest_framework/fields.py", line 569, in run_validation
    self.run_validators(value)
  File "/Users/mac/Desktop/work/game-server/venv/lib/python3.11/site-packages/rest_framework/fields.py", line 591, in run_validators
    validator(value, self)
  File "/Users/mac/Desktop/work/game-server/apps/admin/op_drf/validator.py", line 25, in __call__
    raise APIException(message=self.message)
apps.admin.utils.exceptions.APIException: 用戶已存在

